Workbook

Sheet 貨物
A1: 内部名 | B1: 日本語名 | C1: カテゴリ | D1: カテゴリ名 | E1: 実際の価格 | F1: ゲーム内価格 | G1: ボーナス | H1: 重さ | I1: 色番号 | J1: 色コード | K1: 色 | L1: 貨物係数
A2: None | B2: なし | C2: 0 | D2: =_xlfn.XLOOKUP(C2,カテゴリ!$A:$A,カテゴリ!$B:$B,"不明") -> 専用貨物 | E2: 0 | F2: =ROUND(E2*60,0) -> 0 | G2: 0 | H2: 0 | L2: =IFERROR(FIXED($F2/_xlfn.XLOOKUP("Passagiere",$A:$A,$F:$F),2),"-") -> 0.00
A3: Passagiere | B3: 旅客 | C3: 0 | D3: =_xlfn.XLOOKUP(C3,カテゴリ!$A:$A,カテゴリ!$B:$B,"不明") -> 専用貨物 | E3: 0.5 | F3: =ROUND(E3*60,0) -> 30 | G3: 15 | H3: 70 | I3: 79 | J3: =VLOOKUP($I3,色!$A$2:$B$225,2,FALSE) -> #FF9CD1 | L3: =IFERROR(FIXED($F3/_xlfn.XLOOKUP("Passagiere",$A:$A,$F:$F),2),"-") -> 1.00
A4: Beton | B4: コンクリート | C4: 0 | D4: =_xlfn.XLOOKUP(C4,カテゴリ!$A:$A,カテゴリ!$B:$B,"不明") -> 専用貨物 | E4: 5 | F4: =ROUND(E4*60,0) -> 300 | G4: 10 | H4: 1000 | I4: 11 | J4: =VLOOKUP($I4,色!$A$2:$B$225,2,FALSE) -> #909090 | L4: =IFERROR(FIXED($F4/_xlfn.XLOOKUP("Passagiere",$A:$A,$F:$F),2),"-") -> 10.00
A5: Nutztiere | B5: 家畜 | C5: 0 | D5: =_xlfn.XLOOKUP(C5,カテゴリ!$A:$A,カテゴリ!$B:$B,"不明") -> 専用貨物 | E5: 7 | F5: =ROUND(E5*60,0) -> 420 | G5: 3 | H5: 500 | I5: 190 | J5: =VLOOKUP($I5,色!$A$2:$B$225,2,FALSE) -> #AE6030 | L5: =IFERROR(FIXED($F5/_xlfn.XLOOKUP("Passagiere",$A:$A,$F:$F),2),"-") -> 14.00
A6: catg_Sammelgut | B6: 混載貨物 | C6: 11 | D6: =_xlfn.XLOOKUP(C6,カテゴリ!$A:$A,カテゴリ!$B:$B,"不明") -> 混載貨物 | E6: 0 | F6: =ROUND(E6*60,0) -> 0 | G6: 0 | H6: 0 | L6: =IFERROR(FIXED($F6/_xlfn.XLOOKUP("Passagiere",$A:$A,$F:$F),2),"-") -> 0.00
A7: Alkohol | B7: 酒類 | C7: 11 | D7: =_xlfn.XLOOKUP(C7,カテゴリ!$A:$A,カテゴリ!$B:$B,"不明") -> 混載貨物 | E7: =MAX(280,H7)*50/10000 -> 5.5 | F7: =ROUND(E7*60,0) -> 330 | G7: 15 | H7: 1100 | I7: 157 | J7: =VLOOKUP($I7,色!$A$2:$B$225,2,FALSE) -> #FF952B | L7: =IFERROR(FIXED($F7/_xlfn.XLOOKUP("Passagiere",$A:$A,$F:$F),2),"-") -> 11.00
A8: Baumwolle | B8: 綿花 | C8: 11 | D8: =_xlfn.XLOOKUP(C8,カテゴリ!$A:$A,カテゴリ!$B:$B,"不明") -> 混載貨物 | E8: =MAX(280,H8)*50/10000 -> 2.25 | F8: =ROUND(E8*60,0) -> 135 | G8: 2 | H8: 450 | I8: 214 | J8: =VLOOKUP($I8,色!$A$2:$B$225,2,FALSE) -> #ECECEC | L8: =IFERROR(FIXED($F8/_xlfn.XLOOKUP("Passagiere",$A:$A,$F:$F),2),"-") -> 4.50
A9: Bucher | B9: 書籍 | C9: 11 | D9: =_xlfn.XLOOKUP(C9,カテゴリ!$A:$A,カテゴリ!$B:$B,"不明") -> 混載貨物 | E9: =MAX(280,H9)*50/10000 -> 4.5 | F9: =ROUND(E9*60,0) -> 270 | G9: 5 | H9: 900 | I9: 107 | J9: =VLOOKUP($I9,色!$A$2:$B$225,2,FALSE) -> #765B82 | L9: =IFERROR(FIXED($F9/_xlfn.XLOOKUP("Passagiere",$A:$A,$F:$F),2),"-") -> 9.00
A10: Druckfarbe | B10: 印刷インキ | C10: 11 | D10: =_xlfn.XLOOKUP(C10,カテゴリ!$A:$A,カテゴリ!$B:$B,"不明") -> 混載貨物 | E10: =MAX(280,H10)*50/10000 -> 5.5 | F10: =ROUND(E10*60,0) -> 330 | G10: 1 | H10: 1100 | I10: 208 | J10: =VLOOKUP($I10,色!$A$2:$B$225,2,FALSE) -> #202020 | L10: =IFERROR(FIXED($F10/_xlfn.XLOOKUP("Passagiere",$A:$A,$F:$F),2),"-") -> 11.00
A11: Faser | B11: 繊維 | C11: 11 | D11: =_xlfn.XLOOKUP(C11,カテゴリ!$A:$A,カテゴリ!$B:$B,"不明") -> 混載貨物 | E11: =MAX(280,H11)*50/10000 -> 2 | F11: =ROUND(E11*60,0) -> 120 | G11: 5 | H11: 400 | I11: 111 | J11: =VLOOKUP($I11,色!$A$2:$B$225,2,FALSE) -> #DBAEE6 | L11: =IFERROR(FIXED($F11/_xlfn.XLOOKUP("Passagiere",$A:$A,$F:$F),2),"-") -> 4.00
A12: Gemuse | B12: 野菜 | C12: 11 | D12: =_xlfn.XLOOKUP(C12,カテゴリ!$A:$A,カテゴリ!$B:$B,"不明") -> 混載貨物 | E12: =MAX(280,H12)*50/10000 -> 2.5 | F12: =ROUND(E12*60,0) -> 150 | G12: 25 | H12: 500 | I12: 46 | J12: =VLOOKUP($I12,色!$A$2:$B$225,2,FALSE) -> #6AB92C | L12: =IFERROR(FIXED($F12/_xlfn.XLOOKUP("Passagiere",$A:$A,$F:$F),2),"-") -> 5.00
A13: wurzel_Gemuse | B13: 根菜類 | C13: 11 | D13: =_xlfn.XLOOKUP(C13,カテゴリ!$A:$A,カテゴリ!$B:$B,"不明") -> 混載貨物 | E13: =MAX(280,H13)*50/10000 -> 3 | F13: =ROUND(E13*60,0) -> 180 | G13: 25 | H13: 600 | I13: 191 | J13: =VLOOKUP($I13,色!$A$2:$B$225,2,FALSE) -> #C08040 | L13: =IFERROR(FIXED($F13/_xlfn.XLOOKUP("Passagiere",$A:$A,$F:$F),2),"-") -> 6.00
A14: Gewurze | B14: 香辛料 | C14: 11 | D14: =_xlfn.XLOOKUP(C14,カテゴリ!$A:$A,カテゴリ!$B:$B,"不明") -> 混載貨物 | E14: =MAX(280,H14)*50/10000 -> 1.5 | F14: =ROUND(E14*60,0) -> 90 | G14: 20 | H14: 300 | I14: 154 | J14: =VLOOKUP($I14,色!$A$2:$B$225,2,FALSE) -> #D76B00 | L14: =IFERROR(FIXED($F14/_xlfn.XLOOKUP("Passagiere",$A:$A,$F:$F),2),"-") -> 3.00
A15: Gummi | B15: ゴム | C15: 11 | D15: =_xlfn.XLOOKUP(C15,カテゴリ!$A:$A,カテゴリ!$B:$B,"不明") -> 混載貨物 | E15: =MAX(280,H15)*50/10000 -> 6 | F15: =ROUND(E15*60,0) -> 360 | G15: 3 | H15: 1200 | I15: 217 | J15: =VLOOKUP($I15,色!$A$2:$B$225,2,FALSE) -> #3C2D46 | L15: =IFERROR(FIXED($F15/_xlfn.XLOOKUP("Passagiere",$A:$A,$F:$F),2),"-") -> 12.00
A16: Kleidung | B16: 衣類 | C16: 11 | D16: =_xlfn.XLOOKUP(C16,カテゴリ!$A:$A,カテゴリ!$B:$B,"不明") -> 混載貨物 | E16: =MAX(280,H16)*50/10000 -> 1.4 | F16: =ROUND(E16*60,0) -> 84 | G16: 5 | H16: 200 | I16: 62 | J16: =VLOOKUP($I16,色!$A$2:$B$225,2,FALSE) -> #CB65E1 | L16: =IFERROR(FIXED($F16/_xlfn.XLOOKUP("Passagiere",$A:$A,$F:$F),2),"-") -> 2.80
A17: Moebel | B17: 家具 | C17: 11 | D17: =_xlfn.XLOOKUP(C17,カテゴリ!$A:$A,カテゴリ!$B:$B,"不明") -> 混載貨物 | E17: =MAX(280,H17)*50/10000 -> 1.4 | F17: =ROUND(E17*60,0) -> 84 | G17: 3 | H17: 150 | I17: 188 | J17: =VLOOKUP($I17,色!$A$2:$B$225,2,FALSE) -> #8A4010 | L17: =IFERROR(FIXED($F17/_xlfn.XLOOKUP("Passagiere",$A:$A,$F:$F),2),"-") -> 2.80
A18: Nusse | B18: 種実類 | C18: 11 | D18: =_xlfn.XLOOKUP(C18,カテゴリ!$A:$A,カテゴリ!$B:$B,"不明") -> 混載貨物 | E18: =MAX(280,H18)*50/10000 -> 2.5 | F18: =ROUND(E18*60,0) -> 150 | G18: 20 | H18: 500 | I18: 92 | J18: =VLOOKUP($I18,色!$A$2:$B$225,2,FALSE) -> #A87956 | L18: =IFERROR(FIXED($F18/_xlfn.XLOOKUP("Passagiere",$A:$A,$F:$F),2),"-") -> 5.00
... A29: Wolle | B29: 羊毛 | C29: 11 | D29: =_xlfn.XLOOKUP(C29,カテゴリ!$A:$A,カテゴリ!$B:$B,"不明") -> 混載貨物 | E29: =MAX(280,H29)*50/10000 -> 1.4 | F29: =ROUND(E29*60,0) -> 84 | G29: 2 | H29: 50 | I29: 95 | J29: =VLOOKUP($I29,色!$A$2:$B$225,2,FALSE) -> #FFC782 | L29: =IFERROR(FIXED($F29/_xlfn.XLOOKUP("Passagiere",$A:$A,$F:$F),2),"-") -> 2.80
A30: catg_Kuhlfracht | B30: 冷蔵貨物 | C30: 12 | D30: =_xlfn.XLOOKUP(C30,カテゴリ!$A:$A,カテゴリ!$B:$B,"不明") -> 冷蔵貨物 | E30: 0 | F30: =ROUND(E30*60,0) -> 0 | G30: 0 | H30: 0 | L30: =IFERROR(FIXED($F30/_xlfn.XLOOKUP("Passagiere",$A:$A,$F:$F),2),"-") -> 0.00
A31: Bento | B31: 弁当 | C31: 12 | D31: =_xlfn.XLOOKUP(C31,カテゴリ!$A:$A,カテゴリ!$B:$B,"不明") -> 冷蔵貨物 | E31: =MAX(280,H31)*50/10000*1.2 -> 3 | F31: =ROUND(E31*60,0) -> 180 | G31: 15 | H31: 500 | I31: 7 | J31: =VLOOKUP($I31,色!$A$2:$B$225,2,FALSE) -> #B0D2FF | L31: =IFERROR(FIXED($F31/_xlfn.XLOOKUP("Passagiere",$A:$A,$F:$F),2),"-") -> 6.00
A32: Fischereierzeugnisse | B32: 水産加工品 | C32: 12 | D32: =_xlfn.XLOOKUP(C32,カテゴリ!$A:$A,カテゴリ!$B:$B,"不明") -> 冷蔵貨物 | E32: =MAX(280,H32)*50/10000*1.2 -> 4.8 | F32: =ROUND(E32*60,0) -> 288 | G32: 5 | H32: 800 | I32: 135 | J32: =VLOOKUP($I32,色!$A$2:$B$225,2,FALSE) -> #FF8080 | L32: =IFERROR(FIXED($F32/_xlfn.XLOOKUP("Passagiere",$A:$A,$F:$F),2),"-") -> 9.60
A33: blatt_Gemuse | B33: 葉菜類 | C33: 12 | D33: =_xlfn.XLOOKUP(C33,カテゴリ!$A:$A,カテゴリ!$B:$B,"不明") -> 冷蔵貨物 | E33: =MAX(280,H33)*50/10000*1.2 -> 1.68 | F33: =ROUND(E33*60,0) -> 101 | G33: 25 | H33: 250 | I33: 47 | J33: =VLOOKUP($I33,色!$A$2:$B$225,2,FALSE) -> #79CF34 | L33: =IFERROR(FIXED($F33/_xlfn.XLOOKUP("Passagiere",$A:$A,$F:$F),2),"-") -> 3.37
A34: frucht_Gemuse | B34: 果菜類 | C34: 12 | D34: =_xlfn.XLOOKUP(C34,カテゴリ!$A:$A,カテゴリ!$B:$B,"不明") -> 冷蔵貨物 | E34: =MAX(280,H34)*50/10000*1.2 -> 2.7 | F34: =ROUND(E34*60,0) -> 162 | G34: 25 | H34: 450 | I34: 131 | J34: =VLOOKUP($I34,色!$A$2:$B$225,2,FALSE) -> #C00000 | L34: =IFERROR(FIXED($F34/_xlfn.XLOOKUP("Passagiere",$A:$A,$F:$F),2),"-") -> 5.40
A35: Getraenke | B35: 清涼飲料水 | C35: 12 | D35: =_xlfn.XLOOKUP(C35,カテゴリ!$A:$A,カテゴリ!$B:$B,"不明") -> 冷蔵貨物 | E35: =MAX(280,H35)*50/10000*1.2 -> 5.4 | F35: =ROUND(E35*60,0) -> 324 | G35: 10 | H35: 900 | I35: 103 | J35: =VLOOKUP($I35,色!$A$2:$B$225,2,FALSE) -> #60A0FF | L35: =IFERROR(FIXED($F35/_xlfn.XLOOKUP("Passagiere",$A:$A,$F:$F),2),"-") -> 10.80
A36: Milch | B36: 生乳 | C36: 12 | D36: =_xlfn.XLOOKUP(C36,カテゴリ!$A:$A,カテゴリ!$B:$B,"不明") -> 冷蔵貨物 | E36: =MAX(280,H36)*50/10000*1.2 -> 6.18 | F36: =ROUND(E36*60,0) -> 371 | G36: 10 | H36: 1030 | I36: 175 | J36: =VLOOKUP($I36,色!$A$2:$B$225,2,FALSE) -> #FFFFAC | L36: =IFERROR(FIXED($F36/_xlfn.XLOOKUP("Passagiere",$A:$A,$F:$F),2),"-") -> 12.37
A37: Milchprodukte | B37: 乳製品 | C37: 12 | D37: =_xlfn.XLOOKUP(C37,カテゴリ!$A:$A,カテゴリ!$B:$B,"不明") -> 冷蔵貨物 | E37: =MAX(280,H37)*50/10000*1.2 -> 5.4 | F37: =ROUND(E37*60,0) -> 324 | G37: 15 | H37: 900 | I37: 174 | J37: =VLOOKUP($I37,色!$A$2:$B$225,2,FALSE) -> #FFFF80 | L37: =IFERROR(FIXED($F37/_xlfn.XLOOKUP("Passagiere",$A:$A,$F:$F),2),"-") -> 10.80
A38: stein_Obst | B38: 核果類 | C38: 12 | D38: =_xlfn.XLOOKUP(C38,カテゴリ!$A:$A,カテゴリ!$B:$B,"不明") -> 冷蔵貨物 | E38: =MAX(280,H38)*50/10000*1.2 -> 3 | F38: =ROUND(E38*60,0) -> 180 | G38: 25 | H38: 500 | I38: 76 | J38: =VLOOKUP($I38,色!$A$2:$B$225,2,FALSE) -> #B73E8A | L38: =IFERROR(FIXED($F38/_xlfn.XLOOKUP("Passagiere",$A:$A,$F:$F),2),"-") -> 6.00
A39: Olive | B39: オリーブ | C39: 12 | D39: =_xlfn.XLOOKUP(C39,カテゴリ!$A:$A,カテゴリ!$B:$B,"不明") -> 冷蔵貨物 | E39: =MAX(280,H39)*50/10000*1.2 -> 3.9 | F39: =ROUND(E39*60,0) -> 234 | G39: 25 | H39: 650 | I39: 167 | J39: =VLOOKUP($I39,色!$A$2:$B$225,2,FALSE) -> #80A82C | L39: =IFERROR(FIXED($F39/_xlfn.XLOOKUP("Passagiere",$A:$A,$F:$F),2),"-") -> 7.80
A40: Trauben | B40: ブドウ | C40: 12 | D40: =_xlfn.XLOOKUP(C40,カテゴリ!$A:$A,カテゴリ!$B:$B,"不明") -> 冷蔵貨物 | E40: =MAX(280,H40)*50/10000*1.2 -> 3.3 | F40: =ROUND(E40*60,0) -> 198 | G40: 25 | H40: 550 | I40: 60 | J40: =VLOOKUP($I40,色!$A$2:$B$225,2,FALSE) -> #A045BF | L40: =IFERROR(FIXED($F40/_xlfn.XLOOKUP("Passagiere",$A:$A,$F:$F),2),"-") -> 6.60
A41: catg_Tiefkuehlware | B41: 冷凍貨物 | C41: 13 | D41: =_xlfn.XLOOKUP(C41,カテゴリ!$A:$A,カテゴリ!$B:$B,"不明") -> 冷凍貨物 | E41: 0 | F41: =ROUND(E41*60,0) -> 0 | G41: 0 | H41: 0 | L41: =IFERROR(FIXED($F41/_xlfn.XLOOKUP("Passagiere",$A:$A,$F:$F),2),"-") -> 0.00
A42: Fisch | B42: 魚 | C42: 13 | D42: =_xlfn.XLOOKUP(C42,カテゴリ!$A:$A,カテゴリ!$B:$B,"不明") -> 冷凍貨物 | E42: =MAX(280,H42)*50/10000*1.2+0.2 -> 4.4 | F42: =ROUND(E42*60,0) -> 264 | G42: 15 | H42: 700 | I42: 151 | J42: =VLOOKUP($I42,色!$A$2:$B$225,2,FALSE) -> #0080FF | L42: =IFERROR(FIXED($F42/_xlfn.XLOOKUP("Passagiere",$A:$A,$F:$F),2),"-") -> 8.80
A43: Fleisch | B43: 精肉 | C43: 13 | D43: =_xlfn.XLOOKUP(C43,カテゴリ!$A:$A,カテゴリ!$B:$B,"不明") -> 冷凍貨物 | E43: =MAX(280,H43)*50/10000*1.2+0.2 -> 4.4 | F43: =ROUND(E43*60,0) -> 264 | G43: 15 | H43: 700 | I43: 134 | J43: =VLOOKUP($I43,色!$A$2:$B$225,2,FALSE) -> #FF6060 | L43: =IFERROR(FIXED($F43/_xlfn.XLOOKUP("Passagiere",$A:$A,$F:$F),2),"-") -> 8.80
A44: catg_Kleinsendungen | B44: 小荷物 | C44: 14 | D44: =_xlfn.XLOOKUP(C44,カテゴリ!$A:$A,カテゴリ!$B:$B,"不明") -> 小荷物 | E44: 0 | F44: =ROUND(E44*60,0) -> 0 | G44: 0 | H44: 0 | L44: =IFERROR(FIXED($F44/_xlfn.XLOOKUP("Passagiere",$A:$A,$F:$F),2),"-") -> 0.00
A45: Post | B45: 手荷物 | C45: 14 | D45: =_xlfn.XLOOKUP(C45,カテゴリ!$A:$A,カテゴリ!$B:$B,"不明") -> 小荷物 | E45: =MAX(28,H45)*90/10000 -> 0.252 | F45: =ROUND(E45*60,0) -> 15 | G45: 20 | H45: 20 | I45: 152 | J45: =VLOOKUP($I45,色!$A$2:$B$225,2,FALSE) -> #804000 | L45: =IFERROR(FIXED($F45/_xlfn.XLOOKUP("Passagiere",$A:$A,$F:$F),2),"-") -> 0.50
A46: Zeitung | B46: 新聞 | C46: 14 | D46: =_xlfn.XLOOKUP(C46,カテゴリ!$A:$A,カテゴリ!$B:$B,"不明") -> 小荷物 | E46: =MAX(28,H46)*90/10000 -> 0.765 | F46: =ROUND(E46*60,0) -> 46 | G46: 16 | H46: 85 | I46: 212 | J46: =VLOOKUP($I46,色!$A$2:$B$225,2,FALSE) -> #606060 | L46: =IFERROR(FIXED($F46/_xlfn.XLOOKUP("Passagiere",$A:$A,$F:$F),2),"-") -> 1.53
A47: catg_Massenladen | B47: ばら積み貨物 | C47: 21 | D47: =_xlfn.XLOOKUP(C47,カテゴリ!$A:$A,カテゴリ!$B:$B,"不明") -> ばら積み貨物 | E47: 0 | F47: =ROUND(E47*60,0) -> 0 | G47: 0 | H47: 0 | L47: =IFERROR(FIXED($F47/_xlfn.XLOOKUP("Passagiere",$A:$A,$F:$F),2),"-") -> 0.00
A48: Eisenerz | B48: 鉄鉱石 | C48: 21 | D48: =_xlfn.XLOOKUP(C48,カテゴリ!$A:$A,カテゴリ!$B:$B,"不明") -> ばら積み貨物 | E48: =MAX(280,H48)*70/10000 -> 7 | F48: =ROUND(E48*60,0) -> 420 | G48: 0 | H48: 1000 | I48: 112 | J48: =VLOOKUP($I48,色!$A$2:$B$225,2,FALSE) -> #3F120C | L48: =IFERROR(FIXED($F48/_xlfn.XLOOKUP("Passagiere",$A:$A,$F:$F),2),"-") -> 14.00
A49: Kohle | B49: 石炭 | C49: 21 | D49: =_xlfn.XLOOKUP(C49,カテゴリ!$A:$A,カテゴリ!$B:$B,"不明") -> ばら積み貨物 | E49: =MAX(280,H49)*70/10000 -> 7 | F49: =ROUND(E49*60,0) -> 420 | G49: 0 | H49: 1000 | I49: 176 | J49: =VLOOKUP($I49,色!$A$2:$B$225,2,FALSE) -> #200400 | L49: =IFERROR(FIXED($F49/_xlfn.XLOOKUP("Passagiere",$A:$A,$F:$F),2),"-") -> 14.00
A50: Zement | B50: セメント | C50: 21 | D50: =_xlfn.XLOOKUP(C50,カテゴリ!$A:$A,カテゴリ!$B:$B,"不明") -> ばら積み貨物 | E50: =MAX(280,H50)*70/10000 -> 7 | F50: =ROUND(E50*60,0) -> 420 | G50: 5 | H50: 1000 | I50: 13 | J50: =VLOOKUP($I50,色!$A$2:$B$225,2,FALSE) -> #B5B5B5 | L50: =IFERROR(FIXED($F50/_xlfn.XLOOKUP("Passagiere",$A:$A,$F:$F),2),"-") -> 14.00
...

Sheet カテゴリ
A1: 番号 | B1: カテゴリ名 | C1: 単位目安 | D1: 価格平均 | E1: 価格最大 | F1: 貨物係数
A2: 0 | B2: 専用貨物 | D2: =IFERROR(FIXED(AVERAGEIF(貨物!$C:$C,$A2,貨物!$F:$F),2),"-") -> 187.50 | E2: =IFERROR(FIXED(_xlfn.MAXIFS(貨物!F:F,貨物!C:C,A2),2),"-") -> 420.00 | F2: =IFERROR(FIXED($E2/_xlfn.XLOOKUP("Passagiere",貨物!$A:$A,貨物!$F:$F),2),"-") -> 14.00
A3: 1 | B3: ―未使用― | D3: =IFERROR(FIXED(AVERAGEIF(貨物!$C:$C,$A3,貨物!$F:$F),2),"-") -> - | E3: =IFERROR(FIXED(_xlfn.MAXIFS(貨物!F:F,貨物!C:C,A3),2),"-") -> 0.00 | F3: =IFERROR(FIXED($E3/_xlfn.XLOOKUP("Passagiere",貨物!$A:$A,貨物!$F:$F),2),"-") -> 0.00
A4: 2 | B4: ―未使用― | D4: =IFERROR(FIXED(AVERAGEIF(貨物!$C:$C,$A4,貨物!$F:$F),2),"-") -> - | E4: =IFERROR(FIXED(_xlfn.MAXIFS(貨物!F:F,貨物!C:C,A4),2),"-") -> 0.00 | F4: =IFERROR(FIXED($E4/_xlfn.XLOOKUP("Passagiere",貨物!$A:$A,貨物!$F:$F),2),"-") -> 0.00
A5: 3 | B5: ―未使用― | D5: =IFERROR(FIXED(AVERAGEIF(貨物!$C:$C,$A5,貨物!$F:$F),2),"-") -> - | E5: =IFERROR(FIXED(_xlfn.MAXIFS(貨物!F:F,貨物!C:C,A5),2),"-") -> 0.00 | F5: =IFERROR(FIXED($E5/_xlfn.XLOOKUP("Passagiere",貨物!$A:$A,貨物!$F:$F),2),"-") -> 0.00
A6: 4 | B6: ―未使用― | D6: =IFERROR(FIXED(AVERAGEIF(貨物!$C:$C,$A6,貨物!$F:$F),2),"-") -> - | E6: =IFERROR(FIXED(_xlfn.MAXIFS(貨物!F:F,貨物!C:C,A6),2),"-") -> 0.00 | F6: =IFERROR(FIXED($E6/_xlfn.XLOOKUP("Passagiere",貨物!$A:$A,貨物!$F:$F),2),"-") -> 0.00
A7: 5 | B7: ―未使用― | D7: =IFERROR(FIXED(AVERAGEIF(貨物!$C:$C,$A7,貨物!$F:$F),2),"-") -> - | E7: =IFERROR(FIXED(_xlfn.MAXIFS(貨物!F:F,貨物!C:C,A7),2),"-") -> 0.00 | F7: =IFERROR(FIXED($E7/_xlfn.XLOOKUP("Passagiere",貨物!$A:$A,貨物!$F:$F),2),"-") -> 0.00
A8: 6 | B8: ―未使用― | D8: =IFERROR(FIXED(AVERAGEIF(貨物!$C:$C,$A8,貨物!$F:$F),2),"-") -> - | E8: =IFERROR(FIXED(_xlfn.MAXIFS(貨物!F:F,貨物!C:C,A8),2),"-") -> 0.00 | F8: =IFERROR(FIXED($E8/_xlfn.XLOOKUP("Passagiere",貨物!$A:$A,貨物!$F:$F),2),"-") -> 0.00
A9: 7 | B9: ―未使用― | D9: =IFERROR(FIXED(AVERAGEIF(貨物!$C:$C,$A9,貨物!$F:$F),2),"-") -> - | E9: =IFERROR(FIXED(_xlfn.MAXIFS(貨物!F:F,貨物!C:C,A9),2),"-") -> 0.00 | F9: =IFERROR(FIXED($E9/_xlfn.XLOOKUP("Passagiere",貨物!$A:$A,貨物!$F:$F),2),"-") -> 0.00
A10: 8 | B10: ―未使用― | D10: =IFERROR(FIXED(AVERAGEIF(貨物!$C:$C,$A10,貨物!$F:$F),2),"-") -> - | E10: =IFERROR(FIXED(_xlfn.MAXIFS(貨物!F:F,貨物!C:C,A10),2),"-") -> 0.00 | F10: =IFERROR(FIXED($E10/_xlfn.XLOOKUP("Passagiere",貨物!$A:$A,貨物!$F:$F),2),"-") -> 0.00
A11: 9 | B11: ―未使用― | D11: =IFERROR(FIXED(AVERAGEIF(貨物!$C:$C,$A11,貨物!$F:$F),2),"-") -> - | E11: =IFERROR(FIXED(_xlfn.MAXIFS(貨物!F:F,貨物!C:C,A11),2),"-") -> 0.00 | F11: =IFERROR(FIXED($E11/_xlfn.XLOOKUP("Passagiere",貨物!$A:$A,貨物!$F:$F),2),"-") -> 0.00
A12: 10 | B12: （混載系） | D12: =IFERROR(FIXED(AVERAGEIF(貨物!$C:$C,$A12,貨物!$F:$F),2),"-") -> - | E12: =IFERROR(FIXED(_xlfn.MAXIFS(貨物!F:F,貨物!C:C,A12),2),"-") -> 0.00 | F12: =IFERROR(FIXED($E12/_xlfn.XLOOKUP("Passagiere",貨物!$A:$A,貨物!$F:$F),2),"-") -> 0.00
A13: 11 | B13: 混載貨物 | C13: 1㎥程度 | D13: =IFERROR(FIXED(AVERAGEIF(貨物!$C:$C,$A13,貨物!$F:$F),2),"-") -> 180.25 | E13: =IFERROR(FIXED(_xlfn.MAXIFS(貨物!F:F,貨物!C:C,A13),2),"-") -> 360.00 | F13: =IFERROR(FIXED($E13/_xlfn.XLOOKUP("Passagiere",貨物!$A:$A,貨物!$F:$F),2),"-") -> 12.00
A14: 12 | B14: 冷蔵貨物 | C14: 1㎥程度 | D14: =IFERROR(FIXED(AVERAGEIF(貨物!$C:$C,$A14,貨物!$F:$F),2),"-") -> 214.73 | E14: =IFERROR(FIXED(_xlfn.MAXIFS(貨物!F:F,貨物!C:C,A14),2),"-") -> 371.00 | F14: =IFERROR(FIXED($E14/_xlfn.XLOOKUP("Passagiere",貨物!$A:$A,貨物!$F:$F),2),"-") -> 12.37
A15: 13 | B15: 冷凍貨物 | C15: 1㎥程度 | D15: =IFERROR(FIXED(AVERAGEIF(貨物!$C:$C,$A15,貨物!$F:$F),2),"-") -> 176.00 | E15: =IFERROR(FIXED(_xlfn.MAXIFS(貨物!F:F,貨物!C:C,A15),2),"-") -> 264.00 | F15: =IFERROR(FIXED($E15/_xlfn.XLOOKUP("Passagiere",貨物!$A:$A,貨物!$F:$F),2),"-") -> 8.80
A16: 14 | B16: 小荷物 | C16: 0.1㎥程度 | D16: =IFERROR(FIXED(AVERAGEIF(貨物!$C:$C,$A16,貨物!$F:$F),2),"-") -> 20.33 | E16: =IFERROR(FIXED(_xlfn.MAXIFS(貨物!F:F,貨物!C:C,A16),2),"-") -> 46.00 | F16: =IFERROR(FIXED($E16/_xlfn.XLOOKUP("Passagiere",貨物!$A:$A,貨物!$F:$F),2),"-") -> 1.53
A17: 15 | B17: ―未使用― | D17: =IFERROR(FIXED(AVERAGEIF(貨物!$C:$C,$A17,貨物!$F:$F),2),"-") -> - | E17: =IFERROR(FIXED(_xlfn.MAXIFS(貨物!F:F,貨物!C:C,A17),2),"-") -> 0.00 | F17: =IFERROR(FIXED($E17/_xlfn.XLOOKUP("Passagiere",貨物!$A:$A,貨物!$F:$F),2),"-") -> 0.00
A18: 16 | B18: ―未使用― | D18: =IFERROR(FIXED(AVERAGEIF(貨物!$C:$C,$A18,貨物!$F:$F),2),"-") -> - | E18: =IFERROR(FIXED(_xlfn.MAXIFS(貨物!F:F,貨物!C:C,A18),2),"-") -> 0.00 | F18: =IFERROR(FIXED($E18/_xlfn.XLOOKUP("Passagiere",貨物!$A:$A,貨物!$F:$F),2),"-") -> 0.00
A19: 17 | B19: ―未使用― | D19: =IFERROR(FIXED(AVERAGEIF(貨物!$C:$C,$A19,貨物!$F:$F),2),"-") -> - | E19: =IFERROR(FIXED(_xlfn.MAXIFS(貨物!F:F,貨物!C:C,A19),2),"-") -> 0.00 | F19: =IFERROR(FIXED($E19/_xlfn.XLOOKUP("Passagiere",貨物!$A:$A,貨物!$F:$F),2),"-") -> 0.00
A20: 18 | B20: ―未使用― | D20: =IFERROR(FIXED(AVERAGEIF(貨物!$C:$C,$A20,貨物!$F:$F),2),"-") -> - | E20: =IFERROR(FIXED(_xlfn.MAXIFS(貨物!F:F,貨物!C:C,A20),2),"-") -> 0.00 | F20: =IFERROR(FIXED($E20/_xlfn.XLOOKUP("Passagiere",貨物!$A:$A,貨物!$F:$F),2),"-") -> 0.00
A21: 19 | B21: ―未使用― | D21: =IFERROR(FIXED(AVERAGEIF(貨物!$C:$C,$A21,貨物!$F:$F),2),"-") -> - | E21: =IFERROR(FIXED(_xlfn.MAXIFS(貨物!F:F,貨物!C:C,A21),2),"-") -> 0.00 | F21: =IFERROR(FIXED($E21/_xlfn.XLOOKUP("Passagiere",貨物!$A:$A,貨物!$F:$F),2),"-") -> 0.00
A22: 20 | B22: （ばら荷系） | D22: =IFERROR(FIXED(AVERAGEIF(貨物!$C:$C,$A22,貨物!$F:$F),2),"-") -> - | E22: =IFERROR(FIXED(_xlfn.MAXIFS(貨物!F:F,貨物!C:C,A22),2),"-") -> 0.00 | F22: =IFERROR(FIXED($E22/_xlfn.XLOOKUP("Passagiere",貨物!$A:$A,貨物!$F:$F),2),"-") -> 0.00
A23: 21 | B23: ばら積み貨物 | C23: 1t | D23: =IFERROR(FIXED(AVERAGEIF(貨物!$C:$C,$A23,貨物!$F:$F),2),"-") -> 315.00 | E23: =IFERROR(FIXED(_xlfn.MAXIFS(貨物!F:F,貨物!C:C,A23),2),"-") -> 420.00 | F23: =IFERROR(FIXED($E23/_xlfn.XLOOKUP("Passagiere",貨物!$A:$A,貨物!$F:$F),2),"-") -> 14.00
A24: 22 | B24: 粉粒体貨物 | C24: 1t | D24: =IFERROR(FIXED(AVERAGEIF(貨物!$C:$C,$A24,貨物!$F:$F),2),"-") -> 170.00 | E24: =IFERROR(FIXED(_xlfn.MAXIFS(貨物!F:F,貨物!C:C,A24),2),"-") -> 323.00 | F24: =IFERROR(FIXED($E24/_xlfn.XLOOKUP("Passagiere",貨物!$A:$A,貨物!$F:$F),2),"-") -> 10.77
A25: 23 | B25: 廃棄物 | C25: 1t | D25: =IFERROR(FIXED(AVERAGEIF(貨物!$C:$C,$A25,貨物!$F:$F),2),"-") -> 78.67 | E25: =IFERROR(FIXED(_xlfn.MAXIFS(貨物!F:F,貨物!C:C,A25),2),"-") -> 118.00 | F25: =IFERROR(FIXED($E25/_xlfn.XLOOKUP("Passagiere",貨物!$A:$A,貨物!$F:$F),2),"-") -> 3.93
A26: 24 | B26: 長物貨物 | C26: 1t | D26: =IFERROR(FIXED(AVERAGEIF(貨物!$C:$C,$A26,貨物!$F:$F),2),"-") -> 246.75 | E26: =IFERROR(FIXED(_xlfn.MAXIFS(貨物!F:F,貨物!C:C,A26),2),"-") -> 420.00 | F26: =IFERROR(FIXED($E26/_xlfn.XLOOKUP("Passagiere",貨物!$A:$A,貨物!$F:$F),2),"-") -> 14.00
A27: 25 | B27: 水産物 | C27: 1t | D27: =IFERROR(FIXED(AVERAGEIF(貨物!$C:$C,$A27,貨物!$F:$F),2),"-") -> 210.00 | E27: =IFERROR(FIXED(_xlfn.MAXIFS(貨物!F:F,貨物!C:C,A27),2),"-") -> 420.00 | F27: =IFERROR(FIXED($E27/_xlfn.XLOOKUP("Passagiere",貨物!$A:$A,貨物!$F:$F),2),"-") -> 14.00
A28: 26 | B28: ―未使用― | D28: =IFERROR(FIXED(AVERAGEIF(貨物!$C:$C,$A28,貨物!$F:$F),2),"-") -> - | E28: =IFERROR(FIXED(_xlfn.MAXIFS(貨物!F:F,貨物!C:C,A28),2),"-") -> 0.00 | F28: =IFERROR(FIXED($E28/_xlfn.XLOOKUP("Passagiere",貨物!$A:$A,貨物!$F:$F),2),"-") -> 0.00
A29: 27 | B29: ―未使用― | D29: =IFERROR(FIXED(AVERAGEIF(貨物!$C:$C,$A29,貨物!$F:$F),2),"-") -> - | E29: =IFERROR(FIXED(_xlfn.MAXIFS(貨物!F:F,貨物!C:C,A29),2),"-") -> 0.00 | F29: =IFERROR(FIXED($E29/_xlfn.XLOOKUP("Passagiere",貨物!$A:$A,貨物!$F:$F),2),"-") -> 0.00
A30: 28 | B30: ―未使用― | D30: =IFERROR(FIXED(AVERAGEIF(貨物!$C:$C,$A30,貨物!$F:$F),2),"-") -> - | E30: =IFERROR(FIXED(_xlfn.MAXIFS(貨物!F:F,貨物!C:C,A30),2),"-") -> 0.00 | F30: =IFERROR(FIXED($E30/_xlfn.XLOOKUP("Passagiere",貨物!$A:$A,貨物!$F:$F),2),"-") -> 0.00
A31: 29 | B31: ―未使用― | D31: =IFERROR(FIXED(AVERAGEIF(貨物!$C:$C,$A31,貨物!$F:$F),2),"-") -> - | E31: =IFERROR(FIXED(_xlfn.MAXIFS(貨物!F:F,貨物!C:C,A31),2),"-") -> 0.00 | F31: =IFERROR(FIXED($E31/_xlfn.XLOOKUP("Passagiere",貨物!$A:$A,貨物!$F:$F),2),"-") -> 0.00
A32: 30 | B32: （タンク輸送系） | D32: =IFERROR(FIXED(AVERAGEIF(貨物!$C:$C,$A32,貨物!$F:$F),2),"-") -> - | E32: =IFERROR(FIXED(_xlfn.MAXIFS(貨物!F:F,貨物!C:C,A32),2),"-") -> 0.00 | F32: =IFERROR(FIXED($E32/_xlfn.XLOOKUP("Passagiere",貨物!$A:$A,貨物!$F:$F),2),"-") -> 0.00
A33: 31 | B33: 液体貨物 | C33: 1㎥ | D33: =IFERROR(FIXED(AVERAGEIF(貨物!$C:$C,$A33,貨物!$F:$F),2),"-") -> 294.00 | E33: =IFERROR(FIXED(_xlfn.MAXIFS(貨物!F:F,貨物!C:C,A33),2),"-") -> 420.00 | F33: =IFERROR(FIXED($E33/_xlfn.XLOOKUP("Passagiere",貨物!$A:$A,貨物!$F:$F),2),"-") -> 14.00
A34: 32 | B34: 気体貨物 | C34: 1㎥ | D34: =IFERROR(FIXED(AVERAGEIF(貨物!$C:$C,$A34,貨物!$F:$F),2),"-") -> - | E34: =IFERROR(FIXED(_xlfn.MAXIFS(貨物!F:F,貨物!C:C,A34),2),"-") -> 0.00 | F34: =IFERROR(FIXED($E34/_xlfn.XLOOKUP("Passagiere",貨物!$A:$A,貨物!$F:$F),2),"-") -> 0.00
A35: 33 | B35: ―未使用― | D35: =IFERROR(FIXED(AVERAGEIF(貨物!$C:$C,$A35,貨物!$F:$F),2),"-") -> - | E35: =IFERROR(FIXED(_xlfn.MAXIFS(貨物!F:F,貨物!C:C,A35),2),"-") -> 0.00 | F35: =IFERROR(FIXED($E35/_xlfn.XLOOKUP("Passagiere",貨物!$A:$A,貨物!$F:$F),2),"-") -> 0.00
A36: 34 | B36: ―未使用― | D36: =IFERROR(FIXED(AVERAGEIF(貨物!$C:$C,$A36,貨物!$F:$F),2),"-") -> - | E36: =IFERROR(FIXED(_xlfn.MAXIFS(貨物!F:F,貨物!C:C,A36),2),"-") -> 0.00 | F36: =IFERROR(FIXED($E36/_xlfn.XLOOKUP("Passagiere",貨物!$A:$A,貨物!$F:$F),2),"-") -> 0.00
A37: 35 | B37: ―未使用― | D37: =IFERROR(FIXED(AVERAGEIF(貨物!$C:$C,$A37,貨物!$F:$F),2),"-") -> - | E37: =IFERROR(FIXED(_xlfn.MAXIFS(貨物!F:F,貨物!C:C,A37),2),"-") -> 0.00 | F37: =IFERROR(FIXED($E37/_xlfn.XLOOKUP("Passagiere",貨物!$A:$A,貨物!$F:$F),2),"-") -> 0.00
A38: 36 | B38: ―未使用― | D38: =IFERROR(FIXED(AVERAGEIF(貨物!$C:$C,$A38,貨物!$F:$F),2),"-") -> - | E38: =IFERROR(FIXED(_xlfn.MAXIFS(貨物!F:F,貨物!C:C,A38),2),"-") -> 0.00 | F38: =IFERROR(FIXED($E38/_xlfn.XLOOKUP("Passagiere",貨物!$A:$A,貨物!$F:$F),2),"-") -> 0.00
A39: 37 | B39: ―未使用― | D39: =IFERROR(FIXED(AVERAGEIF(貨物!$C:$C,$A39,貨物!$F:$F),2),"-") -> - | E39: =IFERROR(FIXED(_xlfn.MAXIFS(貨物!F:F,貨物!C:C,A39),2),"-") -> 0.00 | F39: =IFERROR(FIXED($E39/_xlfn.XLOOKUP("Passagiere",貨物!$A:$A,貨物!$F:$F),2),"-") -> 0.00
A40: 38 | B40: ―未使用― | D40: =IFERROR(FIXED(AVERAGEIF(貨物!$C:$C,$A40,貨物!$F:$F),2),"-") -> - | E40: =IFERROR(FIXED(_xlfn.MAXIFS(貨物!F:F,貨物!C:C,A40),2),"-") -> 0.00 | F40: =IFERROR(FIXED($E40/_xlfn.XLOOKUP("Passagiere",貨物!$A:$A,貨物!$F:$F),2),"-") -> 0.00
...

Sheet 色
A1: 色番号 | B1: カラーコード | C1: 色
A2: 0 | B2: #244B67
A3: 1 | B3: #395E7C
A4: 2 | B4: #4C7191
A5: 3 | B5: #6084A7
A6: 4 | B6: #7497BD
A7: 5 | B7: #88ABD3
A8: 6 | B8: #9CBEE9
A9: 7 | B9: #B0D2FF
A10: 8 | B10: #585858
A11: 9 | B11: #6B6B6B
A12: 10 | B12: #7D7D7D
A13: 11 | B13: #909090
... A225: 223 | B225: #C6BFE8
