Workbook

Sheet 128jp
A1: 画像 | B1: 主要クラスタ | C1: 内部名 | D1: 記号 | E1: 種別 | F1: 縦幅 | G1: 横幅 | H1: 一戸建て 住宅数 | I1: 1棟あたり 住民数 | J1: 集合住宅 部屋数 | K1: 1部屋あたり 住民数 | L1: 店舗/工場数 | M1: 1店舗/工場あたり 従業員数 | N1: ビル 階層数 | O1: 1階あたり 住民/従業員数 | P1: 定数 | Q1: Level | R1: 完全な内部名
A2: RES_32_01D | B2: 1 | C2: =_xlfn.XLOOKUP($B2,内部名!$A:$A,内部名!$B:$B,"Unknown") -> Landwirtschaftliche | D2: A | E2: res | F2: 1 | G2: 1 | H2: 2 | I2: 1 | P2: 0 | Q2: =($H2*$I2+$J2*$K2+$L2*$M2+$N2*$O2)/($F2*$G2)+$P2 -> 2 | R2: =CONCATENATE("jpp_",$E2,"_128jp_",$C2,$Q2,$D2) -> jpp_res_128jp_Landwirtschaftliche2A
A3: COM_31_03 | B3: 2 | C3: =_xlfn.XLOOKUP($B3,内部名!$A:$A,内部名!$B:$B,"Unknown") -> NiedrigesGebaeude | D3: A | E3: com | F3: 1 | G3: 1 | L3: 1 | M3: 4 | P3: 0 | Q3: =($H3*$I3+$J3*$K3+$L3*$M3+$N3*$O3)/($F3*$G3)+$P3 -> 4 | R3: =CONCATENATE("jpp_",$E3,"_128jp_",$C3,$Q3,$D3) -> jpp_com_128jp_NiedrigesGebaeude4A
A4: IND_31_07 | B4: 2 | C4: =_xlfn.XLOOKUP($B4,内部名!$A:$A,内部名!$B:$B,"Unknown") -> NiedrigesGebaeude | D4: A | E4: ind | F4: 1 | G4: 1 | L4: 1 | M4: 4 | P4: 0 | Q4: =($H4*$I4+$J4*$K4+$L4*$M4+$N4*$O4)/($F4*$G4)+$P4 -> 4 | R4: =CONCATENATE("jpp_",$E4,"_128jp_",$C4,$Q4,$D4) -> jpp_ind_128jp_NiedrigesGebaeude4A
A5: IND_31_04 | B5: 2 | C5: =_xlfn.XLOOKUP($B5,内部名!$A:$A,内部名!$B:$B,"Unknown") -> NiedrigesGebaeude | D5: A | E5: ind | F5: 1 | G5: 1 | L5: 1 | M5: 12 | P5: 0 | Q5: =($H5*$I5+$J5*$K5+$L5*$M5+$N5*$O5)/($F5*$G5)+$P5 -> 12 | R5: =CONCATENATE("jpp_",$E5,"_128jp_",$C5,$Q5,$D5) -> jpp_ind_128jp_NiedrigesGebaeude12A
A6: IND_31_06 | B6: 2 | C6: =_xlfn.XLOOKUP($B6,内部名!$A:$A,内部名!$B:$B,"Unknown") -> NiedrigesGebaeude | D6: A | E6: ind | F6: 1 | G6: 1 | L6: 1 | M6: 18 | P6: 0 | Q6: =($H6*$I6+$J6*$K6+$L6*$M6+$N6*$O6)/($F6*$G6)+$P6 -> 18 | R6: =CONCATENATE("jpp_",$E6,"_128jp_",$C6,$Q6,$D6) -> jpp_ind_128jp_NiedrigesGebaeude18A
A7: IND_31_09 | B7: 2 | C7: =_xlfn.XLOOKUP($B7,内部名!$A:$A,内部名!$B:$B,"Unknown") -> NiedrigesGebaeude | D7: A | E7: ind | F7: 1 | G7: 1 | L7: 1 | M7: 27 | P7: 0 | Q7: =($H7*$I7+$J7*$K7+$L7*$M7+$N7*$O7)/($F7*$G7)+$P7 -> 27 | R7: =CONCATENATE("jpp_",$E7,"_128jp_",$C7,$Q7,$D7) -> jpp_ind_128jp_NiedrigesGebaeude27A
A8: RES_31_01B | B8: 2 | C8: =_xlfn.XLOOKUP($B8,内部名!$A:$A,内部名!$B:$B,"Unknown") -> NiedrigesGebaeude | D8: A | E8: res | F8: 1 | G8: 1 | H8: 1 | I8: 3 | P8: 0 | Q8: =($H8*$I8+$J8*$K8+$L8*$M8+$N8*$O8)/($F8*$G8)+$P8 -> 3 | R8: =CONCATENATE("jpp_",$E8,"_128jp_",$C8,$Q8,$D8) -> jpp_res_128jp_NiedrigesGebaeude3A
A9: RES_31_01A | B9: 2 | C9: =_xlfn.XLOOKUP($B9,内部名!$A:$A,内部名!$B:$B,"Unknown") -> NiedrigesGebaeude | D9: A | E9: res | F9: 1 | G9: 1 | H9: 1 | I9: 4 | P9: 0 | Q9: =($H9*$I9+$J9*$K9+$L9*$M9+$N9*$O9)/($F9*$G9)+$P9 -> 4 | R9: =CONCATENATE("jpp_",$E9,"_128jp_",$C9,$Q9,$D9) -> jpp_res_128jp_NiedrigesGebaeude4A
A10: RES_31_01C | B10: 2 | C10: =_xlfn.XLOOKUP($B10,内部名!$A:$A,内部名!$B:$B,"Unknown") -> NiedrigesGebaeude | D10: B | E10: res | F10: 1 | G10: 1 | H10: 1 | I10: 4 | P10: 0 | Q10: =($H10*$I10+$J10*$K10+$L10*$M10+$N10*$O10)/($F10*$G10)+$P10 -> 4 | R10: =CONCATENATE("jpp_",$E10,"_128jp_",$C10,$Q10,$D10) -> jpp_res_128jp_NiedrigesGebaeude4B
A11: res.hru01 | B11: 2 | C11: =_xlfn.XLOOKUP($B11,内部名!$A:$A,内部名!$B:$B,"Unknown") -> NiedrigesGebaeude | D11: A | E11: res | F11: 1 | G11: 1 | H11: 1 | I11: 6 | P11: 0 | Q11: =($H11*$I11+$J11*$K11+$L11*$M11+$N11*$O11)/($F11*$G11)+$P11 -> 6 | R11: =CONCATENATE("jpp_",$E11,"_128jp_",$C11,$Q11,$D11) -> jpp_res_128jp_NiedrigesGebaeude6A
A12: RES_31_06A | B12: 2 | C12: =_xlfn.XLOOKUP($B12,内部名!$A:$A,内部名!$B:$B,"Unknown") -> NiedrigesGebaeude | D12: A | E12: res | F12: 1 | G12: 1 | J12: 4 | K12: 2 | P12: 0 | Q12: =($H12*$I12+$J12*$K12+$L12*$M12+$N12*$O12)/($F12*$G12)+$P12 -> 8 | R12: =CONCATENATE("jpp_",$E12,"_128jp_",$C12,$Q12,$D12) -> jpp_res_128jp_NiedrigesGebaeude8A
A13: RES_31_06B | B13: 2 | C13: =_xlfn.XLOOKUP($B13,内部名!$A:$A,内部名!$B:$B,"Unknown") -> NiedrigesGebaeude | D13: B | E13: res | F13: 1 | G13: 1 | J13: 4 | K13: 2 | P13: 0 | Q13: =($H13*$I13+$J13*$K13+$L13*$M13+$N13*$O13)/($F13*$G13)+$P13 -> 8 | R13: =CONCATENATE("jpp_",$E13,"_128jp_",$C13,$Q13,$D13) -> jpp_res_128jp_NiedrigesGebaeude8B
A14: RES_31_05 | B14: 2 | C14: =_xlfn.XLOOKUP($B14,内部名!$A:$A,内部名!$B:$B,"Unknown") -> NiedrigesGebaeude | D14: A | E14: res | F14: 1 | G14: 1 | J14: 6 | K14: 2 | P14: 0 | Q14: =($H14*$I14+$J14*$K14+$L14*$M14+$N14*$O14)/($F14*$G14)+$P14 -> 12 | R14: =CONCATENATE("jpp_",$E14,"_128jp_",$C14,$Q14,$D14) -> jpp_res_128jp_NiedrigesGebaeude12A
A15: RES_31_02A | B15: 2 | C15: =_xlfn.XLOOKUP($B15,内部名!$A:$A,内部名!$B:$B,"Unknown") -> NiedrigesGebaeude | D15: A | E15: res | F15: 1 | G15: 1 | J15: 8 | K15: 2 | P15: 0 | Q15: =($H15*$I15+$J15*$K15+$L15*$M15+$N15*$O15)/($F15*$G15)+$P15 -> 16 | R15: =CONCATENATE("jpp_",$E15,"_128jp_",$C15,$Q15,$D15) -> jpp_res_128jp_NiedrigesGebaeude16A
A16: RES_31_08 | B16: 2 | C16: =_xlfn.XLOOKUP($B16,内部名!$A:$A,内部名!$B:$B,"Unknown") -> NiedrigesGebaeude | D16: B | E16: res | F16: 1 | G16: 1 | J16: 8 | K16: 2 | P16: 0 | Q16: =($H16*$I16+$J16*$K16+$L16*$M16+$N16*$O16)/($F16*$G16)+$P16 -> 16 | R16: =CONCATENATE("jpp_",$E16,"_128jp_",$C16,$Q16,$D16) -> jpp_res_128jp_NiedrigesGebaeude16B
A17: RES_31_07 | B17: 2 | C17: =_xlfn.XLOOKUP($B17,内部名!$A:$A,内部名!$B:$B,"Unknown") -> NiedrigesGebaeude | D17: A | E17: res | F17: 1 | G17: 1 | J17: 12 | K17: 2 | P17: 0 | Q17: =($H17*$I17+$J17*$K17+$L17*$M17+$N17*$O17)/($F17*$G17)+$P17 -> 24 | R17: =CONCATENATE("jpp_",$E17,"_128jp_",$C17,$Q17,$D17) -> jpp_res_128jp_NiedrigesGebaeude24A
A18: RES_31_10 | B18: 2 | C18: =_xlfn.XLOOKUP($B18,内部名!$A:$A,内部名!$B:$B,"Unknown") -> NiedrigesGebaeude | D18: B | E18: res | F18: 1 | G18: 1 | J18: 12 | K18: 2 | P18: 0 | Q18: =($H18*$I18+$J18*$K18+$L18*$M18+$N18*$O18)/($F18*$G18)+$P18 -> 24 | R18: =CONCATENATE("jpp_",$E18,"_128jp_",$C18,$Q18,$D18) -> jpp_res_128jp_NiedrigesGebaeude24B
A19: RES_31_11 | B19: 3 | C19: =_xlfn.XLOOKUP($B19,内部名!$A:$A,内部名!$B:$B,"Unknown") -> Wohnsiedlung | D19: A | E19: res | F19: 1 | G19: 1 | P19: 18 | Q19: =($H19*$I19+$J19*$K19+$L19*$M19+$N19*$O19)/($F19*$G19)+$P19 -> 18 | R19: =CONCATENATE("jpp_",$E19,"_128jp_",$C19,$Q19,$D19) -> jpp_res_128jp_Wohnsiedlung18A
A20: RES_31_09 | B20: 3 | C20: =_xlfn.XLOOKUP($B20,内部名!$A:$A,内部名!$B:$B,"Unknown") -> Wohnsiedlung | D20: B | E20: res | F20: 1 | G20: 1 | J20: 9 | K20: 2 | P20: 0 | Q20: =($H20*$I20+$J20*$K20+$L20*$M20+$N20*$O20)/($F20*$G20)+$P20 -> 18 | R20: =CONCATENATE("jpp_",$E20,"_128jp_",$C20,$Q20,$D20) -> jpp_res_128jp_Wohnsiedlung18B
A21: RES_31_13 | B21: 3 | C21: =_xlfn.XLOOKUP($B21,内部名!$A:$A,内部名!$B:$B,"Unknown") -> Wohnsiedlung | D21: A | E21: res | F21: 1 | G21: 1 | J21: 12 | K21: 2 | P21: 0 | Q21: =($H21*$I21+$J21*$K21+$L21*$M21+$N21*$O21)/($F21*$G21)+$P21 -> 24 | R21: =CONCATENATE("jpp_",$E21,"_128jp_",$C21,$Q21,$D21) -> jpp_res_128jp_Wohnsiedlung24A
A22: RES_31_16 | B22: 3 | C22: =_xlfn.XLOOKUP($B22,内部名!$A:$A,内部名!$B:$B,"Unknown") -> Wohnsiedlung | D22: A | E22: res | F22: 1 | G22: 1 | J22: 24 | K22: 2 | P22: 0 | Q22: =($H22*$I22+$J22*$K22+$L22*$M22+$N22*$O22)/($F22*$G22)+$P22 -> 48 | R22: =CONCATENATE("jpp_",$E22,"_128jp_",$C22,$Q22,$D22) -> jpp_res_128jp_Wohnsiedlung48A
A23: COM_31_09 | B23: 4 | C23: =_xlfn.XLOOKUP($B23,内部名!$A:$A,内部名!$B:$B,"Unknown") -> NiedrigesParzelle | D23: A | E23: com | F23: 1 | G23: 1 | L23: 5 | M23: 2 | N23: 3 | O23: 4 | P23: 0 | Q23: =($H23*$I23+$J23*$K23+$L23*$M23+$N23*$O23)/($F23*$G23)+$P23 -> 22 | R23: =CONCATENATE("jpp_",$E23,"_128jp_",$C23,$Q23,$D23) -> jpp_com_128jp_NiedrigesParzelle22A
A24: RES_31_02C | B24: 4 | C24: =_xlfn.XLOOKUP($B24,内部名!$A:$A,内部名!$B:$B,"Unknown") -> NiedrigesParzelle | D24: A | E24: res | F24: 1 | G24: 1 | H24: 4 | I24: 2 | P24: 0 | Q24: =($H24*$I24+$J24*$K24+$L24*$M24+$N24*$O24)/($F24*$G24)+$P24 -> 8 | R24: =CONCATENATE("jpp_",$E24,"_128jp_",$C24,$Q24,$D24) -> jpp_res_128jp_NiedrigesParzelle8A
A25: RES_31_02B | B25: 4 | C25: =_xlfn.XLOOKUP($B25,内部名!$A:$A,内部名!$B:$B,"Unknown") -> NiedrigesParzelle | D25: A | E25: res | F25: 1 | G25: 1 | H25: 2 | I25: 2 | J25: 6 | K25: 2 | P25: 0 | Q25: =($H25*$I25+$J25*$K25+$L25*$M25+$N25*$O25)/($F25*$G25)+$P25 -> 16 | R25: =CONCATENATE("jpp_",$E25,"_128jp_",$C25,$Q25,$D25) -> jpp_res_128jp_NiedrigesParzelle16A
A26: RES_31_02D | B26: 4 | C26: =_xlfn.XLOOKUP($B26,内部名!$A:$A,内部名!$B:$B,"Unknown") -> NiedrigesParzelle | D26: A | E26: res | F26: 1 | G26: 1 | H26: 3 | I26: 2 | J26: 6 | K26: 2 | P26: 0 | Q26: =($H26*$I26+$J26*$K26+$L26*$M26+$N26*$O26)/($F26*$G26)+$P26 -> 18 | R26: =CONCATENATE("jpp_",$E26,"_128jp_",$C26,$Q26,$D26) -> jpp_res_128jp_NiedrigesParzelle18A
A27: COM_31_05A | B27: 5 | C27: =_xlfn.XLOOKUP($B27,内部名!$A:$A,内部名!$B:$B,"Unknown") -> MittlererGebaeude | D27: A | E27: com | F27: 1 | G27: 1 | J27: 6 | K27: 2 | L27: 1 | M27: 3 | P27: 0 | Q27: =($H27*$I27+$J27*$K27+$L27*$M27+$N27*$O27)/($F27*$G27)+$P27 -> 15 | R27: =CONCATENATE("jpp_",$E27,"_128jp_",$C27,$Q27,$D27) -> jpp_com_128jp_MittlererGebaeude15A
A28: COM_31_06 | B28: 5 | C28: =_xlfn.XLOOKUP($B28,内部名!$A:$A,内部名!$B:$B,"Unknown") -> MittlererGebaeude | D28: A | E28: com | F28: 1 | G28: 1 | L28: 1 | M28: 4 | N28: 3 | O28: 5 | P28: 0 | Q28: =($H28*$I28+$J28*$K28+$L28*$M28+$N28*$O28)/($F28*$G28)+$P28 -> 19 | R28: =CONCATENATE("jpp_",$E28,"_128jp_",$C28,$Q28,$D28) -> jpp_com_128jp_MittlererGebaeude19A
A29: COM_31_10 | B29: 5 | C29: =_xlfn.XLOOKUP($B29,内部名!$A:$A,内部名!$B:$B,"Unknown") -> MittlererGebaeude | D29: A | E29: com | F29: 1 | G29: 1 | L29: 1 | M29: 4 | N29: 5 | O29: 5 | P29: 0 | Q29: =($H29*$I29+$J29*$K29+$L29*$M29+$N29*$O29)/($F29*$G29)+$P29 -> 29 | R29: =CONCATENATE("jpp_",$E29,"_128jp_",$C29,$Q29,$D29) -> jpp_com_128jp_MittlererGebaeude29A
A30: com.hru_01 | B30: 5 | C30: =_xlfn.XLOOKUP($B30,内部名!$A:$A,内部名!$B:$B,"Unknown") -> MittlererGebaeude | D30: B | E30: com | F30: 1 | G30: 1 | L30: 3 | M30: 3 | N30: 5 | O30: 4 | P30: 0 | Q30: =($H30*$I30+$J30*$K30+$L30*$M30+$N30*$O30)/($F30*$G30)+$P30 -> 29 | R30: =CONCATENATE("jpp_",$E30,"_128jp_",$C30,$Q30,$D30) -> jpp_com_128jp_MittlererGebaeude29B
A31: COM_31_55 | B31: 5 | C31: =_xlfn.XLOOKUP($B31,内部名!$A:$A,内部名!$B:$B,"Unknown") -> MittlererGebaeude | D31: A | E31: com | F31: 1 | G31: 1 | N31: 8 | O31: 5 | P31: 0 | Q31: =($H31*$I31+$J31*$K31+$L31*$M31+$N31*$O31)/($F31*$G31)+$P31 -> 40 | R31: =CONCATENATE("jpp_",$E31,"_128jp_",$C31,$Q31,$D31) -> jpp_com_128jp_MittlererGebaeude40A
A32: COM_31_11 | B32: 5 | C32: =_xlfn.XLOOKUP($B32,内部名!$A:$A,内部名!$B:$B,"Unknown") -> MittlererGebaeude | D32: A | E32: ind | F32: 1 | G32: 1 | N32: 3 | O32: 5 | P32: 0 | Q32: =($H32*$I32+$J32*$K32+$L32*$M32+$N32*$O32)/($F32*$G32)+$P32 -> 15 | R32: =CONCATENATE("jpp_",$E32,"_128jp_",$C32,$Q32,$D32) -> jpp_ind_128jp_MittlererGebaeude15A
A33: RES_31_21 | B33: 5 | C33: =_xlfn.XLOOKUP($B33,内部名!$A:$A,内部名!$B:$B,"Unknown") -> MittlererGebaeude | D33: A | E33: res | F33: 1 | G33: 1 | J33: 24 | K33: 2 | L33: 2 | M33: 2 | P33: 0 | Q33: =($H33*$I33+$J33*$K33+$L33*$M33+$N33*$O33)/($F33*$G33)+$P33 -> 52 | R33: =CONCATENATE("jpp_",$E33,"_128jp_",$C33,$Q33,$D33) -> jpp_res_128jp_MittlererGebaeude52A
A34: COM_31_14 | B34: 6 | C34: =_xlfn.XLOOKUP($B34,内部名!$A:$A,内部名!$B:$B,"Unknown") -> MittlererParzelle | D34: A | E34: com | F34: 1 | G34: 1 | L34: 2 | M34: 4 | N34: 3 | O34: 5 | P34: 0 | Q34: =($H34*$I34+$J34*$K34+$L34*$M34+$N34*$O34)/($F34*$G34)+$P34 -> 23 | R34: =CONCATENATE("jpp_",$E34,"_128jp_",$C34,$Q34,$D34) -> jpp_com_128jp_MittlererParzelle23A
A35: COM_31_15 | B35: 6 | C35: =_xlfn.XLOOKUP($B35,内部名!$A:$A,内部名!$B:$B,"Unknown") -> MittlererParzelle | D35: A | E35: com | F35: 1 | G35: 1 | N35: 8 | O35: 4 | P35: 0 | Q35: =($H35*$I35+$J35*$K35+$L35*$M35+$N35*$O35)/($F35*$G35)+$P35 -> 32 | R35: =CONCATENATE("jpp_",$E35,"_128jp_",$C35,$Q35,$D35) -> jpp_com_128jp_MittlererParzelle32A
A36: COM_31_62 | B36: 7 | C36: =_xlfn.XLOOKUP($B36,内部名!$A:$A,内部名!$B:$B,"Unknown") -> Hochhaus | D36: A | E36: com | F36: 1 | G36: 1 | N36: 15 | O36: 4 | P36: 0 | Q36: =($H36*$I36+$J36*$K36+$L36*$M36+$N36*$O36)/($F36*$G36)+$P36 -> 60 | R36: =CONCATENATE("jpp_",$E36,"_128jp_",$C36,$Q36,$D36) -> jpp_com_128jp_Hochhaus60A
A37: COM_31_85 | B37: 7 | C37: =_xlfn.XLOOKUP($B37,内部名!$A:$A,内部名!$B:$B,"Unknown") -> Hochhaus | D37: A | E37: com | F37: 1 | G37: 1 | N37: 19 | O37: 4 | P37: 0 | Q37: =($H37*$I37+$J37*$K37+$L37*$M37+$N37*$O37)/($F37*$G37)+$P37 -> 76 | R37: =CONCATENATE("jpp_",$E37,"_128jp_",$C37,$Q37,$D37) -> jpp_com_128jp_Hochhaus76A
A38: COM_31_90 | B38: 7 | C38: =_xlfn.XLOOKUP($B38,内部名!$A:$A,内部名!$B:$B,"Unknown") -> Hochhaus | D38: A | E38: com | F38: 1 | G38: 1 | N38: 22 | O38: 4 | P38: 0 | Q38: =($H38*$I38+$J38*$K38+$L38*$M38+$N38*$O38)/($F38*$G38)+$P38 -> 88 | R38: =CONCATENATE("jpp_",$E38,"_128jp_",$C38,$Q38,$D38) -> jpp_com_128jp_Hochhaus88A
A39: COM_31_95 | B39: 7 | C39: =_xlfn.XLOOKUP($B39,内部名!$A:$A,内部名!$B:$B,"Unknown") -> Hochhaus | D39: A | E39: com | F39: 1 | G39: 1 | L39: 5 | M39: 4 | N39: 19 | O39: 4 | P39: 0 | Q39: =($H39*$I39+$J39*$K39+$L39*$M39+$N39*$O39)/($F39*$G39)+$P39 -> 96 | R39: =CONCATENATE("jpp_",$E39,"_128jp_",$C39,$Q39,$D39) -> jpp_com_128jp_Hochhaus96A
A40: RES_31_85 | B40: 7 | C40: =_xlfn.XLOOKUP($B40,内部名!$A:$A,内部名!$B:$B,"Unknown") -> Hochhaus | D40: A | E40: res | F40: 1 | G40: 1 | J40: 72 | K40: 1 | P40: 0 | Q40: =($H40*$I40+$J40*$K40+$L40*$M40+$N40*$O40)/($F40*$G40)+$P40 -> 72 | R40: =CONCATENATE("jpp_",$E40,"_128jp_",$C40,$Q40,$D40) -> jpp_res_128jp_Hochhaus72A
...

Sheet 713様
A1: 画像 | B1: 主要クラスタ | C1: 内部名 | D1: 記号 | E1: 種別 | F1: 縦幅 | G1: 横幅 | H1: 一戸建て 住宅数 | I1: 1棟あたり 住民数 | J1: 集合住宅 部屋数 | K1: 1部屋あたり 住民数 | L1: 店舗数 | M1: 1店舗あたり 従業員数 | N1: ビル 階層数 | O1: 1階あたり 住民/従業員数 | P1: 定数 | Q1: Level | R1: 完全な内部名
A2: gokurakuyu | B2: 2 | C2: =_xlfn.XLOOKUP($B2,内部名!$A:$A,内部名!$B:$B,"Unknown") -> NiedrigesGebaeude | D2: A | E2: com | F2: 2 | G2: 2 | L2: 1 | M2: 16 | P2: 0 | Q2: =($H2*$I2+$J2*$K2+$L2*$M2+$N2*$O2)/($F2*$G2)+$P2 -> 4 | R2: =CONCATENATE("jpp_",$E2,"_713_",$C2,$Q2,$D2) -> jpp_com_713_NiedrigesGebaeude4A
A3: danchiC | B3: 3 | C3: =_xlfn.XLOOKUP($B3,内部名!$A:$A,内部名!$B:$B,"Unknown") -> Wohnsiedlung | D3: A | E3: res | F3: 2 | G3: 2 | J3: 30 | K3: 2 | P3: 0 | Q3: =($H3*$I3+$J3*$K3+$L3*$M3+$N3*$O3)/($F3*$G3)+$P3 -> 15 | R3: =CONCATENATE("jpp_",$E3,"_713_",$C3,$Q3,$D3) -> jpp_res_713_Wohnsiedlung15A
A4: danchiE | B4: 3 | C4: =_xlfn.XLOOKUP($B4,内部名!$A:$A,内部名!$B:$B,"Unknown") -> Wohnsiedlung | D4: B | E4: res | F4: 1 | G4: 1 | P4: 15 | Q4: =($H4*$I4+$J4*$K4+$L4*$M4+$N4*$O4)/($F4*$G4)+$P4 -> 15 | R4: =CONCATENATE("jpp_",$E4,"_713_",$C4,$Q4,$D4) -> jpp_res_713_Wohnsiedlung15B
A5: danchiA | B5: 3 | C5: =_xlfn.XLOOKUP($B5,内部名!$A:$A,内部名!$B:$B,"Unknown") -> Wohnsiedlung | D5: A | E5: res | F5: 1 | G5: 1 | J5: 10 | K5: 2 | P5: 0 | Q5: =($H5*$I5+$J5*$K5+$L5*$M5+$N5*$O5)/($F5*$G5)+$P5 -> 20 | R5: =CONCATENATE("jpp_",$E5,"_713_",$C5,$Q5,$D5) -> jpp_res_713_Wohnsiedlung20A
A6: danchiD | B6: 3 | C6: =_xlfn.XLOOKUP($B6,内部名!$A:$A,内部名!$B:$B,"Unknown") -> Wohnsiedlung | D6: B | E6: res | F6: 2 | G6: 2 | J6: 40 | K6: 2 | P6: 0 | Q6: =($H6*$I6+$J6*$K6+$L6*$M6+$N6*$O6)/($F6*$G6)+$P6 -> 20 | R6: =CONCATENATE("jpp_",$E6,"_713_",$C6,$Q6,$D6) -> jpp_res_713_Wohnsiedlung20B
A7: danchiB | B7: 3 | C7: =_xlfn.XLOOKUP($B7,内部名!$A:$A,内部名!$B:$B,"Unknown") -> Wohnsiedlung | D7: A | E7: res | F7: 1 | G7: 1 | J7: 15 | K7: 2 | P7: 0 | Q7: =($H7*$I7+$J7*$K7+$L7*$M7+$N7*$O7)/($F7*$G7)+$P7 -> 30 | R7: =CONCATENATE("jpp_",$E7,"_713_",$C7,$Q7,$D7) -> jpp_res_713_Wohnsiedlung30A

Sheet ウィルソン様
A1: 画像 | B1: 主要クラスタ | C1: 内部名 | D1: 記号 | E1: 種別 | F1: 縦幅 | G1: 横幅 | H1: 一戸建て 住宅数 | I1: 1棟あたり 住民数 | J1: 集合住宅 部屋数 | K1: 1部屋あたり 住民数 | L1: 店舗/工場数 | M1: 1店舗/工場あたり 従業員数 | N1: ビル 階層数 | O1: 1階あたり 住民/従業員数 | P1: 定数 | Q1: Level | R1: 完全な内部名
A2: tanbo1x1 | B2: 1 | C2: =_xlfn.XLOOKUP($B2,内部名!$A:$A,内部名!$B:$B,"Unknown") -> Landwirtschaftliche | D2: A | E2: com | F2: 1 | G2: 1 | P2: 0 | Q2: =($H2*$I2+$J2*$K2+$L2*$M2+$N2*$O2)/($F2*$G2)+$P2 -> 0 | R2: =CONCATENATE("jpp_",$E2,"_wilson_",$C2,$Q2,$D2) -> jpp_com_wilson_Landwirtschaftliche0A
A3: hatake1x1 | B3: 1 | C3: =_xlfn.XLOOKUP($B3,内部名!$A:$A,内部名!$B:$B,"Unknown") -> Landwirtschaftliche | D3: B | E3: com | F3: 1 | G3: 1 | P3: 0 | Q3: =($H3*$I3+$J3*$K3+$L3*$M3+$N3*$O3)/($F3*$G3)+$P3 -> 0 | R3: =CONCATENATE("jpp_",$E3,"_wilson_",$C3,$Q3,$D3) -> jpp_com_wilson_Landwirtschaftliche0B
A4: tanbokyu1x1 | B4: 1 | C4: =_xlfn.XLOOKUP($B4,内部名!$A:$A,内部名!$B:$B,"Unknown") -> Landwirtschaftliche | D4: C | E4: com | F4: 1 | G4: 1 | P4: 0 | Q4: =($H4*$I4+$J4*$K4+$L4*$M4+$N4*$O4)/($F4*$G4)+$P4 -> 0 | R4: =CONCATENATE("jpp_",$E4,"_wilson_",$C4,$Q4,$D4) -> jpp_com_wilson_Landwirtschaftliche0C
A5: tanbo1x2 | B5: 1 | C5: =_xlfn.XLOOKUP($B5,内部名!$A:$A,内部名!$B:$B,"Unknown") -> Landwirtschaftliche | D5: D | E5: com | F5: 1 | G5: 2 | P5: 0 | Q5: =($H5*$I5+$J5*$K5+$L5*$M5+$N5*$O5)/($F5*$G5)+$P5 -> 0 | R5: =CONCATENATE("jpp_",$E5,"_wilson_",$C5,$Q5,$D5) -> jpp_com_wilson_Landwirtschaftliche0D
A6: hatake1x2 | B6: 1 | C6: =_xlfn.XLOOKUP($B6,内部名!$A:$A,内部名!$B:$B,"Unknown") -> Landwirtschaftliche | D6: E | E6: com | F6: 1 | G6: 2 | P6: 0 | Q6: =($H6*$I6+$J6*$K6+$L6*$M6+$N6*$O6)/($F6*$G6)+$P6 -> 0 | R6: =CONCATENATE("jpp_",$E6,"_wilson_",$C6,$Q6,$D6) -> jpp_com_wilson_Landwirtschaftliche0E
A7: tanbokyu1x2 | B7: 1 | C7: =_xlfn.XLOOKUP($B7,内部名!$A:$A,内部名!$B:$B,"Unknown") -> Landwirtschaftliche | D7: F | E7: com | F7: 1 | G7: 2 | P7: 0 | Q7: =($H7*$I7+$J7*$K7+$L7*$M7+$N7*$O7)/($F7*$G7)+$P7 -> 0 | R7: =CONCATENATE("jpp_",$E7,"_wilson_",$C7,$Q7,$D7) -> jpp_com_wilson_Landwirtschaftliche0F
A8: tanbo2x2 | B8: 1 | C8: =_xlfn.XLOOKUP($B8,内部名!$A:$A,内部名!$B:$B,"Unknown") -> Landwirtschaftliche | D8: G | E8: com | F8: 2 | G8: 2 | P8: 0 | Q8: =($H8*$I8+$J8*$K8+$L8*$M8+$N8*$O8)/($F8*$G8)+$P8 -> 0 | R8: =CONCATENATE("jpp_",$E8,"_wilson_",$C8,$Q8,$D8) -> jpp_com_wilson_Landwirtschaftliche0G
A9: hatake2x2 | B9: 1 | C9: =_xlfn.XLOOKUP($B9,内部名!$A:$A,内部名!$B:$B,"Unknown") -> Landwirtschaftliche | D9: H | E9: com | F9: 2 | G9: 2 | P9: 0 | Q9: =($H9*$I9+$J9*$K9+$L9*$M9+$N9*$O9)/($F9*$G9)+$P9 -> 0 | R9: =CONCATENATE("jpp_",$E9,"_wilson_",$C9,$Q9,$D9) -> jpp_com_wilson_Landwirtschaftliche0H
A10: tanbokyu2x2 | B10: 1 | C10: =_xlfn.XLOOKUP($B10,内部名!$A:$A,内部名!$B:$B,"Unknown") -> Landwirtschaftliche | D10: I | E10: com | F10: 2 | G10: 2 | P10: 0 | Q10: =($H10*$I10+$J10*$K10+$L10*$M10+$N10*$O10)/($F10*$G10)+$P10 -> 0 | R10: =CONCATENATE("jpp_",$E10,"_wilson_",$C10,$Q10,$D10) -> jpp_com_wilson_Landwirtschaftliche0I
A11: tanbo1x1 | B11: 1 | C11: =_xlfn.XLOOKUP($B11,内部名!$A:$A,内部名!$B:$B,"Unknown") -> Landwirtschaftliche | D11: A | E11: ind | F11: 1 | G11: 1 | P11: 0 | Q11: =($H11*$I11+$J11*$K11+$L11*$M11+$N11*$O11)/($F11*$G11)+$P11 -> 0 | R11: =CONCATENATE("jpp_",$E11,"_wilson_",$C11,$Q11,$D11) -> jpp_ind_wilson_Landwirtschaftliche0A
A12: hatake1x1 | B12: 1 | C12: =_xlfn.XLOOKUP($B12,内部名!$A:$A,内部名!$B:$B,"Unknown") -> Landwirtschaftliche | D12: B | E12: ind | F12: 1 | G12: 1 | P12: 0 | Q12: =($H12*$I12+$J12*$K12+$L12*$M12+$N12*$O12)/($F12*$G12)+$P12 -> 0 | R12: =CONCATENATE("jpp_",$E12,"_wilson_",$C12,$Q12,$D12) -> jpp_ind_wilson_Landwirtschaftliche0B
A13: tanbokyu1x1 | B13: 1 | C13: =_xlfn.XLOOKUP($B13,内部名!$A:$A,内部名!$B:$B,"Unknown") -> Landwirtschaftliche | D13: C | E13: ind | F13: 1 | G13: 1 | P13: 0 | Q13: =($H13*$I13+$J13*$K13+$L13*$M13+$N13*$O13)/($F13*$G13)+$P13 -> 0 | R13: =CONCATENATE("jpp_",$E13,"_wilson_",$C13,$Q13,$D13) -> jpp_ind_wilson_Landwirtschaftliche0C
... A28: tanbokyu2x2 | B28: 1 | C28: =_xlfn.XLOOKUP($B28,内部名!$A:$A,内部名!$B:$B,"Unknown") -> Landwirtschaftliche | D28: I | E28: res | F28: 2 | G28: 2 | P28: 0 | Q28: =($H28*$I28+$J28*$K28+$L28*$M28+$N28*$O28)/($F28*$G28)+$P28 -> 0 | R28: =CONCATENATE("jpp_",$E28,"_wilson_",$C28,$Q28,$D28) -> jpp_res_wilson_Landwirtschaftliche0I

Sheet 内部名
A1: 主要クラスタ | B1: 内部名 | C1: 日本語訳
A2: 1 | B2: Landwirtschaftliche | C2: 農業的
A3: 2 | B3: NiedrigesGebaeude | C3: 低層建物
A4: 3 | B4: Wohnsiedlung | C4: 団地
A5: 4 | B5: NiedrigesParzelle | C5: 低層区画
A6: 5 | B6: MittlererGebaeude | C6: 中層ビル
A7: 6 | B7: MittlererParzelle | C7: 中層区画
A8: 7 | B8: Hochhaus | C8: 高層ビル
