Workbook

Sheet 電車
A1: 形式 | B1: 定員 | C1: 出力 | D1: ギア比（実車） | E1: ギア比（ゲーム内） | F1: 最高速度 | G1: 維持費 | H1: 価格
A2: 国鉄風通勤形電車1
A3: 4扉先頭/後尾車A | B3: 136 | C3: 480 | D3: 607 | E3: =FIXED(D3*2/7,0,TRUE) -> 173 | F3: 120 | G3: =FIXED(0.004*(B3*F3^0.5/10+((C3*E3)*F3^0.4/1000))*0.75,2,TRUE) -> 2.14 | H3: =FIXED((800*B3*(F3^0.5))/10+(C3*E3*F3^0.7)/20,0,TRUE) -> 237675
A4: 4扉先頭/後尾車B | B4: 136 | C4: 480 | D4: 607 | E4: =FIXED(D4*2/7,0,TRUE) -> 173 | F4: 121 | G4: =FIXED(0.004*(B4*F4^0.5/10+((C4*E4)*F4^0.4/1000))*0.75,2,TRUE) -> 2.15 | H4: =FIXED((800*B4*(F4^0.5))/10+(C4*E4*F4^0.7)/20,0,TRUE) -> 238861
A5: 4扉中間車 | B5: 144 | C5: 480 | D5: 607 | E5: =FIXED(D5*2/7,0,TRUE) -> 173 | F5: 120 | G5: =FIXED(0.004*(B5*F5^0.5/10+((C5*E5)*F5^0.4/1000))*0.75,2,TRUE) -> 2.16 | H5: =FIXED((800*B5*(F5^0.5))/10+(C5*E5*F5^0.7)/20,0,TRUE) -> 244686
A6: 6扉中間車 | B6: 157 | C6: 480 | D6: 607 | E6: =FIXED(D6*2/7,0,TRUE) -> 173 | F6: 120 | G6: =FIXED(0.004*(B6*F6^0.5/10+((C6*E6)*F6^0.4/1000))*0.75,2,TRUE) -> 2.21 | H6: =FIXED((800*B6*(F6^0.5))/10+(C6*E6*F6^0.7)/20,0,TRUE) -> 256079

Sheet 気動車
A1: 形式 | B1: 定員 | C1: 出力 | D1: ギア比 | E1: 最高速度 | F1: 維持費 | G1: 価格
A2: キハ５８ | B2: 84 | C2: 270 | D2: 130 | E2: 95 | F2: =0.004*(B2*E2^0.5/10+(2*(C2*D2)*E2^0.4/1000))*0.85 -> 1.7537538 | G2: =(800*B2*(E2^0.5))/10+(2*C2*D2*E2^0.7)/20 -> 150556.16 | I2: 85
A3: キハ２８ | B3: 84 | C3: 135 | D3: 130 | E3: 95 | F3: =0.004*(B3*E3^0.5/10+(2*(C3*D3)*E3^0.4/1000))*0.85 -> 1.0160611 | G3: =(800*B3*(E3^0.5))/10+(2*C3*D3*E3^0.7)/20 -> 108027.31
A4: キロ２８ | B4: 52 | C4: 135 | D4: 130 | E4: 95 | F4: =0.004*(B4*E4^0.5/10+(2*(C4*D4)*E4^0.4/1000))*0.85 -> 0.91001601 | G4: =(800*B4*(E4^0.5))/10+(2*C4*D4*E4^0.7)/20 -> 83075.515
A5: １０連 | F5: =F2*10 -> 17.537538 | G5: =G2*10 -> 1505561.6
A7: 形式 | B7: 定員 | C7: 出力 | D7: ギア比 | E7: 最高速度 | F7: 維持費 | G7: 価格
A8: キハ35 | B8: 132 | C8: 135 | D8: 130 | E8: 95 | F8: =0.004*(B8*E8^0.5/10+(2*(C8*D8)*E8^0.4/1000))*0.85 -> 1.1751288 | G8: =(800*B8*(E8^0.5))/10+(2*C8*D8*E8^0.7)/20 -> 145455 | I8: 85
A9: キハ30 | B9: 128 | C9: 135 | D9: 130 | E9: 95 | F9: =0.004*(B9*E9^0.5/10+(2*(C9*D9)*E9^0.4/1000))*0.85 -> 1.1618732 | G9: =(800*B9*(E9^0.5))/10+(2*C9*D9*E9^0.7)/20 -> 142336.02
A10: キロ36 | B10: 136 | C10: 135 | D10: 130 | E10: 95 | F10: =0.004*(B10*E10^0.5/10+(2*(C10*D10)*E10^0.4/1000))*0.85 -> 1.1883845 | G10: =(800*B10*(E10^0.5))/10+(2*C10*D10*E10^0.7)/20 -> 148573.97
A11: １０連 | F11: =F8*10 -> 11.751288 | G11: =G8*10 -> 1454550
A13: 形式 | B13: 定員 | C13: 出力 | D13: ギア比 | E13: 最高速度 | F13: 維持費 | G13: 価格
A14: キハ120 | B14: 112 | C14: 248 | D14: 117 | E14: 95 | F14: =0.004*(B14*E14^0.5/10+(2*(C14*D14)*E14^0.4/1000))*0.7 -> 1.3100787 | G14: =(800*B14*(E14^0.5))/10+(2*C14*D14*E14^0.7)/20 -> 157645.64 | I14: 70
A16: 形式 | B16: 定員 | C16: 出力 | D16: ギア比 | E16: 最高速度 | F16: 維持費 | G16: 価格
A17: キハ42000 | B17: 125 | C17: 113 | D17: 125 | E17: 75 | F17: =0.004*(B17*E17^0.5/10+(2*(C17*D17)*E17^0.4/1000)) -> 1.0684943 | G17: =(800*B17*(E17^0.5))/10+(2*C17*D17*E17^0.7)/20 -> 115611.45 | I17: 100

Sheet 客車
A1: 形式 | B1: 定員 | C1: 出力 | D1: ギア比 | E1: 最高速度 | F1: 維持費 | G1: 価格
A2: スハ43 | B2: 88 | E2: 95 | F2: =0.004*(B2*E2^0.5/10+((C2*D2)*E2^0.4/1000))*0.95 -> 0.3259328 | G2: =(800*B2*(E2^0.5))/10+C2*D2*E2/20 -> 68617.432 | I2: 95
A3: スハフ42 | B3: 80 | E3: 95 | F3: =0.004*(B3*E3^0.5/10+((C3*D3)*E3^0.4/1000))*0.95 -> 0.29630255 | G3: =(800*B3*(E3^0.5))/10+C3*D3*E3/20 -> 62379.484
A4: スハ44 | B4: 80 | E4: 95 | F4: =0.004*(B4*E4^0.5/10+((C4*D4)*E4^0.4/1000))*0.95 -> 0.29630255 | G4: =(800*B4*(E4^0.5))/10+C4*D4*E4/20 -> 62379.484
A5: スハフ４３ | B5: 72 | E5: 95 | F5: =0.004*(B5*E5^0.5/10+((C5*D5)*E5^0.4/1000))*0.95 -> 0.26667229 | G5: =(800*B5*(E5^0.5))/10+C5*D5*E5/20 -> 56141.535
A6: スハニ35 | B6: 48 | E6: 95 | F6: =0.004*(B6*E6^0.5/10+((C6*D6)*E6^0.4/1000))*0.95 -> 0.17778153 | G6: =(800*B6*(E6^0.5))/10+C6*D6*E6/20 -> 37427.69
A7: スロ60 | B7: 44 | E7: 95 | F7: =0.004*(B7*E7^0.5/10+((C7*D7)*E7^0.4/1000))*0.95 -> 0.1629664 | G7: =(800*B7*(E7^0.5))/10+C7*D7*E7/20 -> 34308.716
A8: スロ51 | B8: 52 | E8: 95 | F8: =0.004*(B8*E8^0.5/10+((C8*D8)*E8^0.4/1000))*0.95 -> 0.19259666 | G8: =(800*B8*(E8^0.5))/10+C8*D8*E8/20 -> 40546.664
A10: スハニ35650 | B10: 48 | E10: 95 | F10: =0.004*(B10*E10^0.5/10+((C10*D10)*E10^0.4/1000)) -> 0.18713845 | G10: =(800*B10*(E10^0.5))/10+C10*D10*E10/20 -> 37427.69 | I10: 100
A11: スロ30750 | B11: 60 | E11: 95 | F11: =0.004*(B11*E11^0.5/10+((C11*D11)*E11^0.4/1000)) -> 0.23392306 | G11: =(800*B11*(E11^0.5))/10+C11*D11*E11/20 -> 46784.613
A12: スハ32600 | B12: 88 | E12: 95 | F12: =0.004*(B12*E12^0.5/10+((C12*D12)*E12^0.4/1000)) -> 0.34308716 | G12: =(800*B12*(E12^0.5))/10+C12*D12*E12/20 -> 68617.432
A13: スイテ37000 | B13: 24 | E13: 95 | F13: =0.004*(B13*E13^0.5/10+((C13*D13)*E13^0.4/1000)) -> 0.093569226 | G13: =(800*B13*(E13^0.5))/10+C13*D13*E13/20 -> 18713.845
A14: スハフ34200 | B14: 80 | E14: 95 | F14: =0.004*(B14*E14^0.5/10+((C14*D14)*E14^0.4/1000)) -> 0.31189742 | G14: =(800*B14*(E14^0.5))/10+C14*D14*E14/20 -> 62379.484
A16: オハ50 | B16: 112 | E16: 95 | F16: =0.004*(B16*E16^0.5/10+((C16*D16)*E16^0.4/1000))*0.8 -> 0.34932511 | G16: =(800*B16*(E16^0.5))/10+C16*D16*E16/20 -> 87331.277 | I16: 80
A17: オハフ50 | B17: 92 | E17: 95 | F17: =0.004*(B17*E17^0.5/10+((C17*D17)*E17^0.4/1000))*0.8 -> 0.28694563 | G17: =(800*B17*(E17^0.5))/10+C17*D17*E17/20 -> 71736.406 | I17: 80

Sheet 貨車
A1: 形式 | B1: 積載量 | C1: 係数 | D1: 定員（換算） | E1: 出力 | F1: ギア比 | G1: 最高速度 | H1: 維持費 | I1: 価格 | J1: 登場 | K1: 係数
A2: ばら | B2: ton
A3: トラ6000 | B3: 17 | C3: 2.2 | D3: =B3*C3 -> 37.4 | G3: 65 | H3: =0.004*(D3*G3^0.5/10+((E3*F3)*G3^0.4/1000))*K3*100 -> 12.061138 | I3: =(800*D3*(G3^0.5))/10+E3*F3*G3/20 -> 24122.275 | J3: 1941 | K3: 1
A4: トキ900 | B4: 30 | C4: 2.2 | D4: =B4*C4 -> 66 | G4: 65 | H4: =0.004*(D4*G4^0.5/10+((E4*F4)*G4^0.4/1000))*K4*100 -> 34.054977 | I4: =(800*D4*(G4^0.5))/10+E4*F4*G4/20 -> 42568.721 | J4: 1943 | K4: 1.6
A5: トラ35000 | B5: 17 | C5: 2.2 | D5: =B5*C5 -> 37.4 | G5: 75 | H5: =0.004*(D5*G5^0.5/10+((E5*F5)*G5^0.4/1000))*K5*100 -> 11.660166 | I5: =(800*D5*(G5^0.5))/10+E5*F5*G5/20 -> 25911.48 | J5: 1956 | K5: 0.9
A8: 混載 | B8: 100 kg
A9: ワム1 | B9: 150 | C9: 0.4 | D9: =B9*C9 -> 60 | G9: 65 | H9: =0.004*(D9*G9^0.5/10+((E9*F9)*G9^0.4/1000))*K9*100 -> 20.31689 | I9: =(800*D9*(G9^0.5))/10+E9*F9*G9/20 -> 38698.837 | J9: 1915 | K9: 1.05
A10: ワム3500 | B10: 150 | C10: 0.4 | D10: =B10*C10 -> 60 | G10: 65 | H10: =0.004*(D10*G10^0.5/10+((E10*F10)*G10^0.4/1000))*K10*100 -> 20.31689 | I10: =(800*D10*(G10^0.5))/10+E10*F10*G10/20 -> 38698.837 | J10: 1917 | K10: 1.05
A11: ワム23000 | B11: 150 | C11: 0.4 | D11: =B11*C11 -> 60 | G11: 65 | H11: =0.004*(D11*G11^0.5/10+((E11*F11)*G11^0.4/1000))*K11*100 -> 19.349419 | I11: =(800*D11*(G11^0.5))/10+E11*F11*G11/20 -> 38698.837 | J11: 1938 | K11: 1
A12: ワム90000 | B12: 150 | C12: 0.4 | D12: =B12*C12 -> 60 | G12: 75 | H12: =0.004*(D12*G12^0.5/10+((E12*F12)*G12^0.4/1000))*K12*100 -> 18.706149 | I12: =(800*D12*(G12^0.5))/10+E12*F12*G12/20 -> 41569.219 | J12: 1953 | K12: 0.9
A13: ワキ8000 | B13: 300 | C13: 0.4 | D13: =B13*C13 -> 120 | G13: 85 | H13: =0.004*(D13*G13^0.5/10+((E13*F13)*G13^0.4/1000))*K13*100 -> 37.615741 | I13: =(800*D13*(G13^0.5))/10+E13*F13*G13/20 -> 88507.627 | J13: 1970 | K13: 0.85
A16: パレット | B16: 1 ton
A17: ワム80000 | B17: 14 | C17: 3 | D17: =B17*C17 -> 42 | G17: 75 | H17: =0.004*(D17*G17^0.5/10+((E17*F17)*G17^0.4/1000))*K17*100 -> 12.366843 | I17: =(800*D17*(G17^0.5))/10+E17*F17*G17/20 -> 29098.454 | K17: 0.85
A18: ワム280000 | B18: 14 | C18: 3 | D18: =B18*C18 -> 42 | G18: 75 | H18: =0.004*(D18*G18^0.5/10+((E18*F18)*G18^0.4/1000))*K18*100 -> 11.639381 | I18: =(800*D18*(G18^0.5))/10+E18*F18*G18/20 -> 29098.454 | K18: 0.8
A19: ワム380000 | B19: 14 | C19: 3 | D19: =B19*C19 -> 42 | G19: 75 | H19: =0.004*(D19*G19^0.5/10+((E19*F19)*G19^0.4/1000))*K19*100 -> 10.91192 | I19: =(800*D19*(G19^0.5))/10+E19*F19*G19/20 -> 29098.454 | K19: 0.75
A20: ワキ5000 | B20: 24 | C20: 3 | D20: =B20*C20 -> 72 | G20: 85 | H20: =0.004*(D20*G20^0.5/10+((E20*F20)*G20^0.4/1000))*K20*100 -> 22.569445 | I20: =(800*D20*(G20^0.5))/10+E20*F20*G20/20 -> 53104.576 | K20: 0.85
A21: ワキ10000 | B21: 24 | C21: 3 | D21: =B21*C21 -> 72 | G21: 100 | H21: =0.004*(D21*G21^0.5/10+((E21*F21)*G21^0.4/1000))*K21*100 -> 31.68 | I21: =(800*D21*(G21^0.5))/10+E21*F21*G21/20 -> 57600 | J21: 1966 | K21: 1.1
A22: ワキ50000 | B22: 24 | C22: 3 | D22: =B22*C22 -> 72 | G22: 95 | H22: =0.004*(D22*G22^0.5/10+((E22*F22)*G22^0.4/1000))*K22*100 -> 26.667229 | I22: =(800*D22*(G22^0.5))/10+E22*F22*G22/20 -> 56141.535 | J22: 1977 | K22: 0.95
A26: 石油類 | B26: 1 ton
A27: タ600 | B27: 10 | C27: 2.5 | D27: =B27*C27 -> 25 | G27: 65 | H27: =0.004*(D27*G27^0.5/10+((E27*F27)*G27^0.4/1000))*K27*100 -> 9.6747093 | I27: =(800*D27*(G27^0.5))/10+E27*F27*G27/20 -> 16124.515 | J27: 1907 | K27: 1.2
A31: 長物 | B31: 1 ton
A32: チキ1000 | B32: 35 | C32: 2 | D32: =B32*C32 -> 70 | G32: 85 | H32: =0.004*(D32*G32^0.5/10+((E32*F32)*G32^0.4/1000))*K32*100 -> 27.105461 | I32: =(800*D32*(G32^0.5))/10+E32*F32*G32/20 -> 51629.449 | J32: 1929 | K32: 1.05
A33: チキ1500 | B33: 35 | C33: 2 | D33: =B33*C33 -> 70 | G33: 95 | H33: =0.004*(D33*G33^0.5/10+((E33*F33)*G33^0.4/1000))*K33*100 -> 28.655575 | I33: =(800*D33*(G33^0.5))/10+E33*F33*G33/20 -> 54582.048 | J33: 1934 | K33: 1.05
A34: チサ1600 | B34: 20 | C34: 2 | D34: =B34*C34 -> 40 | G34: 65 | H34: =0.004*(D34*G34^0.5/10+((E34*F34)*G34^0.4/1000))*K34*100 -> 12.899612 | I34: =(800*D34*(G34^0.5))/10+E34*F34*G34/20 -> 25799.225 | J34: 1946 | K34: 1
A36: 冷蔵加工食品 | B36: 100 kg
A37: レ2900 | B37: 120 | C37: 0.5 | D37: =B37*C37 -> 60 | G37: 65 | H37: =0.004*(D37*G37^0.5/10+((E37*F37)*G37^0.4/1000))*K37*100 -> 20.31689 | I37: =(800*D37*(G37^0.5))/10+E37*F37*G37/20 -> 38698.837 | J37: 1927 | K37: 1.05
A38: ワム580000 | B38: 150 | C38: 0.5 | D38: =B38*C38 -> 75 | G38: 75 | H38: =0.004*(D38*G38^0.5/10+((E38*F38)*G38^0.4/1000))*K38*100 -> 22.083648 | I38: =(800*D38*(G38^0.5))/10+E38*F38*G38/20 -> 51961.524 | J38: 1967 | K38: 0.85
A41: 鮮魚 | B41: 1 ton
A42: レ5000 | B42: 12 | C42: 5 | D42: =B42*C42 -> 60 | G42: 65 | H42: =0.004*(D42*G42^0.5/10+((E42*F42)*G42^0.4/1000))*K42*100 -> 19.349419 | I42: =(800*D42*(G42^0.5))/10+E42*F42*G42/20 -> 38698.837 | J42: 1936 | K42: 1
A43: レム5000 | B43: 15 | C43: 5 | D43: =B43*C43 -> 75 | G43: 75 | H43: =0.004*(D43*G43^0.5/10+((E43*F43)*G43^0.4/1000))*K43*100 -> 22.083648 | I43: =(800*D43*(G43^0.5))/10+E43*F43*G43/20 -> 51961.524 | J43: 1964 | K43: 0.85
A44: レサ5000 | B44: 24 | C44: 5 | D44: =B44*C44 -> 120 | G44: 85 | H44: =0.004*(D44*G44^0.5/10+((E44*F44)*G44^0.4/1000))*K44*100 -> 37.615741 | I44: =(800*D44*(G44^0.5))/10+E44*F44*G44/20 -> 88507.627 | J44: 1968 | K44: 0.85
A45: レサ10000 | B45: 24 | C45: 5 | D45: =B45*C45 -> 120 | G45: 100 | H45: =0.004*(D45*G45^0.5/10+((E45*F45)*G45^0.4/1000))*K45*100 -> 52.8 | I45: =(800*D45*(G45^0.5))/10+E45*F45*G45/20 -> 96000 | J45: 1966 | K45: 1.1
A48: 鉄鋼 | B48: 1 ton
A49: チキ1000 | B49: 20 | C49: 2.8 | D49: =B49*C49 -> 56 | G49: 85 | H49: =0.004*(D49*G49^0.5/10+((E49*F49)*G49^0.4/1000))*K49*100 -> 21.684369 | I49: =(800*D49*(G49^0.5))/10+E49*F49*G49/20 -> 41303.559 | J49: 1929 | K49: 1.05
A50: ワキ9000 | B50: 30 | C50: 2.8 | D50: =B50*C50 -> 84 | G50: 85 | H50: =0.004*(D50*G50^0.5/10+((E50*F50)*G50^0.4/1000))*K50*100 -> 26.331019 | I50: =(800*D50*(G50^0.5))/10+E50*F50*G50/20 -> 61955.339 | J50: 1966 | K50: 0.85
A55: 木材チップ | B55: 1 ton
A56: トラ6000 | B56: 8 | C56: 3 | D56: =B56*C56 -> 24 | G56: 65 | H56: =0.004*(D56*G56^0.5/10+((E56*F56)*G56^0.4/1000))*K56*100 -> 7.3527791 | I56: =(800*D56*(G56^0.5))/10+E56*F56*G56/20 -> 15479.535 | J56: 1941 | K56: 0.95
A57: トラ90000 | B57: 12 | C57: 3 | D57: =B57*C57 -> 36 | G57: 75 | H57: =0.004*(D57*G57^0.5/10+((E57*F57)*G57^0.4/1000))*K57*100 -> 11.223689 | I57: =(800*D57*(G57^0.5))/10+E57*F57*G57/20 -> 24941.532 | J57: 1964 | K57: 0.9
A58: ワム480000 | B58: 15 | C58: 3 | D58: =B58*C58 -> 45 | G58: 75 | H58: =0.004*(D58*G58^0.5/10+((E58*F58)*G58^0.4/1000))*K58*100 -> 13.250189 | I58: =(800*D58*(G58^0.5))/10+E58*F58*G58/20 -> 31176.915 | J58: 1998 | K58: 0.85
A63: 化成品
...

Sheet 機関車
A1: 形式 | B1: 定員 | C1: 出力 | D1: ギア比 | E1: 最高速度 | F1: 維持費 | G1: 価格
A2: ED16 | B2: 0 | C2: 900 | D2: 144 | E2: 65 | F2: =0.004*(B2*E2^0.5/10+((C2*D2)*E2^0.4/1000)) -> 2.7531529 | G2: =(800*B2*(E2^0.5))/10+(C2*D2*E2^0.7)/20 -> 120396.64 | I2: 100
A3: ＥＦ10 | B3: 0 | C3: 1350 | D3: 144 | E3: 75 | F3: =0.004*(B3*E3^0.5/10+((C3*D3)*E3^0.4/1000)) -> 4.3730129 | G3: =(800*B3*(E3^0.5))/10+(C3*D3*E3^0.7)/20 -> 199622.34 | I3: 100
A4: EF12 | B4: 0 | C4: 1600 | D4: 144 | E4: 75 | F4: =0.004*(B4*E4^0.5/10+((C4*D4)*E4^0.4/1000))*95 -> 492.36886 | G4: =(800*B4*(E4^0.5))/10+(C4*D4*E4^0.7)/20 -> 236589.44 | I4: 95
A5: EF15 | B5: 0 | C5: 1900 | D5: 144 | E5: 75 | F5: =0.004*(B5*E5^0.5/10+((C5*D5)*E5^0.4/1000))*90 -> 553.91497 | G5: =(800*B5*(E5^0.5))/10+(C5*D5*E5^0.7)/20 -> 280949.96 | I5: 90
A6: ＥＦ53 | B6: 0 | C6: 1350 | D6: 144 | E6: 95 | F6: =0.004*(B6*E6^0.5/10+((C6*D6)*E6^0.4/1000)) -> 4.8066854 | G6: =(800*B6*(E6^0.5))/10+(C6*D6*E6^0.7)/20 -> 235544.4 | I6: 100
A7: ＥＦ56 | B7: 0 | C7: 1350 | D7: 144 | E7: 95 | F7: =0.004*(B7*E7^0.5/10+((C7*D7)*E7^0.4/1000))*0.95 -> 4.5663511 | G7: =(800*B7*(E7^0.5))/10+(C7*D7*E7^0.7)/20 -> 235544.4 | I7: 95
A9: ＥＦ５８ | B9: 0 | C9: 1900 | D9: 144 | E9: 100 | F9: =0.004*(B9*E9^0.5/10+((C9*D9)*E9^0.4/1000))*0.95 -> 6.5599373 | G9: =(800*B9*(E9^0.5))/10+(C9*D9*E9^0.7)/20 -> 343626.06 | I9: 95
A10: EF80 | B10: 0 | C10: 1950 | D10: 144 | E10: 100 | F10: =0.004*(B10*E10^0.5/10+((C10*D10)*E10^0.4/1000))*0.85 -> 6.023876 | G10: =(800*B10*(E10^0.5))/10+(C10*D10*E10^0.7)/20 -> 352668.85 | I10: 85
A11: EF65 | B11: 0 | C11: 2550 | D11: 144 | E11: 100 | F11: =0.004*(B11*E11^0.5/10+((C11*D11)*E11^0.4/1000))*0.85 -> 7.8773763 | G11: =(800*B11*(E11^0.5))/10+(C11*D11*E11^0.7)/20 -> 461182.35 | I11: 85
A12: EF66 | B12: 0 | C12: 3900 | D12: 166 | E12: 110 | F12: =0.004*(B12*E12^0.5/10+((C12*D12)*E12^0.4/1000))*0.8 -> 13.579374 | G12: =(800*B12*(E12^0.5))/10+(C12*D12*E12^0.7)/20 -> 869195.72 | I12: 80
A13: EF66_100 | B13: 0 | C13: 3900 | D13: 166 | E13: 110 | F13: =0.004*(B13*E13^0.5/10+((C13*D13)*E13^0.4/1000))*0.75 -> 12.730663 | G13: =(800*B13*(E13^0.5))/10+(C13*D13*E13^0.7)/20 -> 869195.72 | I13: 75
A14: EF71 | B14: 0 | C14: 2700 | D14: 150 | E14: 100 | F14: =0.004*(B14*E14^0.5/10+((C14*D14)*E14^0.4/1000))*0.85 -> 8.6882826 | G14: =(800*B14*(E14^0.5))/10+(C14*D14*E14^0.7)/20 -> 508657 | I14: 85
A15: ED75 | B15: 0 | C15: 1900 | D15: 150 | E15: 100 | F15: =0.004*(B15*E15^0.5/10+((C15*D15)*E15^0.4/1000))*0.85 -> 6.1139767 | G15: =(800*B15*(E15^0.5))/10+(C15*D15*E15^0.7)/20 -> 357943.82 | I15: 85
A17: DE10 | B17: 0 | C17: 1250 | D17: 130 | E17: 85 | F17: =0.004*(B17*E17^0.5/10+(2*(C17*D17)*E17^0.4/1000))*I17/100 -> 6.1489493 | G17: =(800*B17*(E17^0.5))/10+(2*C17*D17*E17^0.7)/20 -> 364289.47 | I17: 80
A18: DD13 | B18: 0 | C18: 750 | D18: 130 | E18: 70 | F18: =0.004*(B18*E18^0.5/10+(2*(C18*D18)*E18^0.4/1000))*I18/100 -> 3.6270433 | G18: =(800*B18*(E18^0.5))/10+(2*C18*D18*E18^0.7)/20 -> 190797.75 | I18: 85
A19: DD51 | B19: 0 | C19: 1500 | D19: 130 | E19: 95 | F19: =0.004*(B19*E19^0.5/10+(2*(C19*D19)*E19^0.4/1000))*I19/100 -> 8.1965854 | G19: =(800*B19*(E19^0.5))/10+(2*C19*D19*E19^0.7)/20 -> 472542.78 | I19: 85
A20: DD51 | B20: 0 | C20: 1650 | D20: 130 | E20: 95 | F20: =0.004*(B20*E20^0.5/10+(2*(C20*D20)*E20^0.4/1000))*I20/100 -> 8.4858766 | G20: =(800*B20*(E20^0.5))/10+(2*C20*D20*E20^0.7)/20 -> 519797.06 | I20: 80
A27: C61 | B27: 0 | C27: 1035 | D27: 130 | E27: 110 | F27: =0.004*(B27*E27^0.5/10+(2*(C27*D27)*E27^0.4/1000))*I27/100 -> 6.7027708 | G27: =(800*B27*(E27^0.5))/10+(2*C27*D27*E27^0.7)/20 -> 361292.2 | I27: 95
A28: D51 | B28: 0 | C28: 960 | D28: 130 | E28: 75 | F28: =0.004*(B28*E28^0.5/10+(2*(C28*D28)*E28^0.4/1000))*I28/100 -> 5.333996 | G28: =(800*B28*(E28^0.5))/10+(2*C28*D28*E28^0.7)/20 -> 256305.23 | I28: 95

Sheet モノレール
A1: 形式 | B1: 定員 | C1: 出力 | D1: ギア比 | E1: 最高速度 | F1: 維持費 | G1: 価格
A2: 湘南5000a | B2: 72 | C2: 220 | D2: 100 | E2: 75 | F2: =0.004*(B2*E2^0.5/10+((2*C2*D2)*E2^0.4/1000))*0.65 -> 0.80547473 | G2: =(800*B2*(E2^0.5))/10+(2*C2*D2*E2^0.7)/20 -> 95065.075 | I2: 65
A3: 湘南5000b | B3: 80 | C3: 220 | D3: 100 | E3: 75 | F3: =0.004*(B3*E3^0.5/10+((2*C3*D3)*E3^0.4/1000))*0.65 -> 0.82348806 | G3: =(800*B3*(E3^0.5))/10+(2*C3*D3*E3^0.7)/20 -> 100607.64
A4: 湘南5000c | B4: 72 | C4: 220 | D4: 100 | E4: 75 | F4: =0.004*(B4*E4^0.5/10+((2*C4*D4)*E4^0.4/1000))*0.65 -> 0.80547473 | G4: =(800*B4*(E4^0.5))/10+(2*C4*D4*E4^0.7)/20 -> 95065.075
A5: ３連 | F5: =F2+F3+F4 -> 2.4344375 | G5: =G2+G3+G4 -> 290737.79

Sheet 旅客自動車
A1: 形式 | B1: 定員 | C1: 最高速度 | D1: 出力 | E1: ギア比 | F1: 維持費 | G1: 価格
A2: ボンネットバス1 | B2: 48 | C2: 60 | D2: 90 | E2: 50 | F2: =FIXED(0.008*(B2*C2^0.5/10+((4*D2*E2)*C2^0.4/1000)),2,TRUE)*100 -> 104 | G2: =FIXED((800*B2*(C2^0.5))/10+(2*D2*E2*C2^0.7)/20,0,TRUE)*100 -> 3765000
A4: 1968年式路線バス | B4: 66 | C4: 70 | D4: 128 | E4: 71 | F4: =FIXED(0.008*(B4*C4^0.5/10+((4*D4*E4)*C4^0.4/1000)),2,TRUE)*100 -> 203 | G4: =FIXED((800*B4*(C4^0.5))/10+(2*D4*E4*C4^0.7)/20,0,TRUE)*100 -> 6196000
A5: 1984年式路線バス | B5: 73 | C5: 70 | D5: 162 | E5: 71 | F5: =FIXED(0.008*(B5*C5^0.5/10+((4*D5*E5)*C5^0.4/1000)),2,TRUE)*100 -> 250 | G5: =FIXED((800*B5*(C5^0.5))/10+(2*D5*E5*C5^0.7)/20,0,TRUE)*100 -> 7136900
A6: 2000年式路線バス | B6: 68 | C6: 80 | D6: 177 | E6: 71 | F6: =FIXED(0.008*(B6*C6^0.5/10+((4*D6*E6)*C6^0.4/1000)),2,TRUE)*100 -> 281 | G6: =FIXED((800*B6*(C6^0.5))/10+(2*D6*E6*C6^0.7)/20,0,TRUE)*100 -> 7565900
A8: 1992年式小型バス | B8: 29 | C8: 110 | D8: 110 | E8: 71 | F8: =FIXED(0.008*(B8*C8^0.5/10+((4*D8*E8)*C8^0.4/1000)),2,TRUE)*100 -> 188 | G8: =FIXED((800*B8*(C8^0.5))/10+(2*D8*E8*C8^0.7)/20,0,TRUE)*100 -> 4530400
A9: 2006年式小型バス（ロング） | B9: 35 | C9: 80 | D9: 132 | E9: 71 | F9: =FIXED(0.008*(B9*C9^0.5/10+((4*D9*E9)*C9^0.4/1000)),2,TRUE)*100 -> 198 | G9: =FIXED((800*B9*(C9^0.5))/10+(2*D9*E9*C9^0.7)/20,0,TRUE)*100 -> 4518100
A10: 2006年式小型バス（ショート） | B10: 29 | C10: 80 | D10: 132 | E10: 71 | F10: =FIXED(0.008*(B10*C10^0.5/10+((4*D10*E10)*C10^0.4/1000)),2,TRUE)*100 -> 194 | G10: =FIXED((800*B10*(C10^0.5))/10+(2*D10*E10*C10^0.7)/20,0,TRUE)*100 -> 4088800

Sheet 貨物自動車
A1: 形式 | B1: 積載量 | C1: 貨物 | D1: 係数 | E1: 定員（換算） | F1: 出力 | G1: ギア比 | H1: 最高速度 | I1: 維持費 | J1: 価格 | K1: 登場 | L1: 係数
A2: 1989年式小型トラック | B2: 10 | C2: 混載 | D2: =_xlfn.XLOOKUP(C2,貨物係数!$B$2:$B$18,貨物係数!$C$2:$C$18) -> 12 | E2: =B2*D2 -> 120 | F2: 90 | G2: 50 | H2: 60 | I2: =FIXED(0.008*(E2*H2^0.5/10+((4*F2*G2)*H2^0.4/1000))*L2,2,TRUE)*100 -> 104 | J2: =FIXED((800*E2*(H2^0.5))/10+(2*F2*G2*H2^0.7)/20,0,TRUE)*100 -> 8226700 | K2: 1989 | L2: 0.7
B3: 10 | C3: 冷蔵 | D3: =_xlfn.XLOOKUP(C3,貨物係数!$B$2:$B$18,貨物係数!$C$2:$C$18) -> 14 | E3: =B3*D3 -> 140 | F3: 90 | G3: 50 | H3: 60 | I3: =FIXED(0.008*(E3*H3^0.5/10+((4*F3*G3)*H3^0.4/1000))*L3,2,TRUE)*100 -> 113 | J3: =FIXED((800*E3*(H3^0.5))/10+(2*F3*G3*H3^0.7)/20,0,TRUE)*100 -> 9466000 | K3: 1989 | L3: 0.7
B4: 10 | C4: 冷凍 | D4: =_xlfn.XLOOKUP(C4,貨物係数!$B$2:$B$18,貨物係数!$C$2:$C$18) -> 16 | E4: =B4*D4 -> 160 | F4: 90 | G4: 50 | H4: 60 | I4: =FIXED(0.008*(E4*H4^0.5/10+((4*F4*G4)*H4^0.4/1000))*L4,2,TRUE)*100 -> 121 | J4: =FIXED((800*E4*(H4^0.5))/10+(2*F4*G4*H4^0.7)/20,0,TRUE)*100 -> 10705400 | K4: 1989 | L4: 0.7
B5: 100 | C5: 小荷物 | D5: =_xlfn.XLOOKUP(C5,貨物係数!$B$2:$B$18,貨物係数!$C$2:$C$18) -> 1.53 | E5: =B5*D5 -> 153 | F5: 90 | G5: 50 | H5: 60 | I5: =FIXED(0.008*(E5*H5^0.5/10+((4*F5*G5)*H5^0.4/1000))*L5,2,TRUE)*100 -> 118 | J5: =FIXED((800*E5*(H5^0.5))/10+(2*F5*G5*H5^0.7)/20,0,TRUE)*100 -> 10271600 | K5: 1989 | L5: 0.7
B6: 10 | C6: 水産物 | D6: =_xlfn.XLOOKUP(C6,貨物係数!$B$2:$B$18,貨物係数!$C$2:$C$18) -> 14 | E6: =B6*D6 -> 140 | F6: 90 | G6: 50 | H6: 60 | I6: =FIXED(0.008*(E6*H6^0.5/10+((4*F6*G6)*H6^0.4/1000))*L6,2,TRUE)*100 -> 113 | J6: =FIXED((800*E6*(H6^0.5))/10+(2*F6*G6*H6^0.7)/20,0,TRUE)*100 -> 9466000 | K6: 1989 | L6: 0.7
I7: =FIXED(0.008*(E7*H7^0.5/10+((4*F7*G7)*H7^0.4/1000))*L7,2,TRUE)*100 -> 0
A8: 1988年式トラック | B8: 20 | C8: 混載 | D8: =_xlfn.XLOOKUP(C8,貨物係数!$B$2:$B$18,貨物係数!$C$2:$C$18) -> 12 | E8: =B8*D8 -> 240 | F8: 200 | G8: 70 | H8: 110 | I8: =FIXED(0.008*(E8*H8^0.5/10+((4*F8*G8)*H8^0.4/1000))*L8,2,TRUE)*100 -> 124 | J8: =FIXED((800*E8*(H8^0.5))/10+(2*F8*G8*H8^0.7)/20,0,TRUE)*100 -> 23896400 | K8: 1988 | L8: 0.25
B9: 20 | C9: 冷蔵 | D9: =_xlfn.XLOOKUP(C9,貨物係数!$B$2:$B$18,貨物係数!$C$2:$C$18) -> 14 | E9: =B9*D9 -> 280 | F9: 200 | G9: 70 | H9: 110 | I9: =FIXED(0.008*(E9*H9^0.5/10+((4*F9*G9)*H9^0.4/1000))*L9,2,TRUE)*100 -> 132 | J9: =FIXED((800*E9*(H9^0.5))/10+(2*F9*G9*H9^0.7)/20,0,TRUE)*100 -> 27252600 | K9: 1988 | L9: 0.25
B10: 20 | C10: 冷凍 | D10: =_xlfn.XLOOKUP(C10,貨物係数!$B$2:$B$18,貨物係数!$C$2:$C$18) -> 16 | E10: =B10*D10 -> 320 | F10: 200 | G10: 70 | H10: 110 | I10: =FIXED(0.008*(E10*H10^0.5/10+((4*F10*G10)*H10^0.4/1000))*L10,2,TRUE)*100 -> 141 | J10: =FIXED((800*E10*(H10^0.5))/10+(2*F10*G10*H10^0.7)/20,0,TRUE)*100 -> 30608800 | K10: 1988 | L10: 0.25
B11: 200 | C11: 小荷物 | D11: =_xlfn.XLOOKUP(C11,貨物係数!$B$2:$B$18,貨物係数!$C$2:$C$18) -> 1.53 | E11: =B11*D11 -> 306 | F11: 200 | G11: 70 | H11: 110 | I11: =FIXED(0.008*(E11*H11^0.5/10+((4*F11*G11)*H11^0.4/1000))*L11,2,TRUE)*100 -> 138 | J11: =FIXED((800*E11*(H11^0.5))/10+(2*F11*G11*H11^0.7)/20,0,TRUE)*100 -> 29434100 | K11: 1988 | L11: 0.25
B12: 20 | C12: 水産物 | D12: =_xlfn.XLOOKUP(C12,貨物係数!$B$2:$B$18,貨物係数!$C$2:$C$18) -> 14 | E12: =B12*D12 -> 280 | F12: 200 | G12: 70 | H12: 110 | I12: =FIXED(0.008*(E12*H12^0.5/10+((4*F12*G12)*H12^0.4/1000))*L12,2,TRUE)*100 -> 132 | J12: =FIXED((800*E12*(H12^0.5))/10+(2*F12*G12*H12^0.7)/20,0,TRUE)*100 -> 27252600 | K12: 1988 | L12: 0.25
I13: =FIXED(0.008*(E13*H13^0.5/10+((4*F13*G13)*H13^0.4/1000))*L13,2,TRUE)*100 -> 0
A14: 1988年式コンテナトラック | B14: 18 | C14: 混載 | D14: =_xlfn.XLOOKUP(C14,貨物係数!$B$2:$B$18,貨物係数!$C$2:$C$18) -> 12 | E14: =B14*D14 -> 216 | F14: 200 | G14: 70 | H14: 110 | I14: =FIXED(0.008*(E14*H14^0.5/10+((4*F14*G14)*H14^0.4/1000))*L14,2,TRUE)*100 -> 119 | J14: =FIXED((800*E14*(H14^0.5))/10+(2*F14*G14*H14^0.7)/20,0,TRUE)*100 -> 21882700 | K14: 1988 | L14: 0.25
I15: =FIXED(0.008*(E15*H15^0.5/10+((4*F15*G15)*H15^0.4/1000))*L15,2,TRUE)*100 -> 0
A16: 1988年式平台トラック | B16: 15 | C16: 混載 | D16: =_xlfn.XLOOKUP(C16,貨物係数!$B$2:$B$18,貨物係数!$C$2:$C$18) -> 12 | E16: =B16*D16 -> 180 | F16: 200 | G16: 70 | H16: 110 | I16: =FIXED(0.008*(E16*H16^0.5/10+((4*F16*G16)*H16^0.4/1000))*L16,2,TRUE)*100 -> 111 | J16: =FIXED((800*E16*(H16^0.5))/10+(2*F16*G16*H16^0.7)/20,0,TRUE)*100 -> 18862100 | K16: 1988 | L16: 0.25
B17: 10 | C17: ばら | D17: =_xlfn.XLOOKUP(C17,貨物係数!$B$2:$B$18,貨物係数!$C$2:$C$18) -> 14 | E17: =B17*D17 -> 140 | F17: 200 | G17: 70 | H17: 110 | I17: =FIXED(0.008*(E17*H17^0.5/10+((4*F17*G17)*H17^0.4/1000))*L17,2,TRUE)*100 -> 103 | J17: =FIXED((800*E17*(H17^0.5))/10+(2*F17*G17*H17^0.7)/20,0,TRUE)*100 -> 15505900 | K17: 1988 | L17: 0.25
B18: 10 | C18: 粉粒体 | D18: =_xlfn.XLOOKUP(C18,貨物係数!$B$2:$B$18,貨物係数!$C$2:$C$18) -> 10.77 | E18: =B18*D18 -> 107.7 | F18: 200 | G18: 70 | H18: 110 | I18: =FIXED(0.008*(E18*H18^0.5/10+((4*F18*G18)*H18^0.4/1000))*L18,2,TRUE)*100 -> 96 | J18: =FIXED((800*E18*(H18^0.5))/10+(2*F18*G18*H18^0.7)/20,0,TRUE)*100 -> 12795800 | K18: 1988 | L18: 0.25
B19: 15 | C19: 廃棄物 | D19: =_xlfn.XLOOKUP(C19,貨物係数!$B$2:$B$18,貨物係数!$C$2:$C$18) -> 3.93 | E19: =B19*D19 -> 58.95 | F19: 200 | G19: 70 | H19: 110 | I19: =FIXED(0.008*(E19*H19^0.5/10+((4*F19*G19)*H19^0.4/1000))*L19,2,TRUE)*100 -> 86 | J19: =FIXED((800*E19*(H19^0.5))/10+(2*F19*G19*H19^0.7)/20,0,TRUE)*100 -> 8705400 | K19: 1988 | L19: 0.25
B20: 20 | C20: 長物 | D20: =_xlfn.XLOOKUP(C20,貨物係数!$B$2:$B$18,貨物係数!$C$2:$C$18) -> 14 | E20: =B20*D20 -> 280 | F20: 200 | G20: 70 | H20: 110 | I20: =FIXED(0.008*(E20*H20^0.5/10+((4*F20*G20)*H20^0.4/1000))*L20,2,TRUE)*100 -> 132 | J20: =FIXED((800*E20*(H20^0.5))/10+(2*F20*G20*H20^0.7)/20,0,TRUE)*100 -> 27252600 | K20: 1988 | L20: 0.25
I21: =FIXED(0.008*(E21*H21^0.5/10+((4*F21*G21)*H21^0.4/1000))*L21,2,TRUE)*100 -> 0
A22: 1970年式重ダンプトラック | B22: 180 | C22: ばら | D22: =_xlfn.XLOOKUP(C22,貨物係数!$B$2:$B$18,貨物係数!$C$2:$C$18) -> 14 | E22: =B22*D22 -> 2520 | F22: 1335 | G22: 95 | H22: 35 | I22: =FIXED(0.008*(E22*H22^0.5/10+((4*F22*G22)*H22^0.4/1000))*L22,2,TRUE)*100 -> 863 | J22: =FIXED((800*E22*(H22^0.5))/10+(2*F22*G22*H22^0.7)/20,0,TRUE)*100 -> 134545700 | K22: 1970 | L22: 0.3
I23: =FIXED(0.008*(E23*H23^0.5/10+((4*F23*G23)*H23^0.4/1000))*L23,2,TRUE)*100 -> 0
A24: 1990年式タンクローリー | B24: 20 | C24: 液体 | D24: =_xlfn.XLOOKUP(C24,貨物係数!$B$2:$B$18,貨物係数!$C$2:$C$18) -> 14 | E24: =B24*D24 -> 280 | F24: 250 | G24: 70 | H24: 100 | I24: =FIXED(0.008*(E24*H24^0.5/10+((4*F24*G24)*H24^0.4/1000))*L24,2,TRUE)*100 -> 144 | J24: =FIXED((800*E24*(H24^0.5))/10+(2*F24*G24*H24^0.7)/20,0,TRUE)*100 -> 26795800 | K24: 1990 | L24: 0.25

Sheet 旅客船
A1: 形式 | B1: 定員 | C1: 出力 | D1: ギア比 | E1: 最高速度 | F1: 維持費 | G1: 価格
A2: 伊予丸 | B2: 2050 | C2: 4870 | D2: 100 | E2: =16.21*1.852 -> 30.02092 | F2: =0.004*(B2*E2^0.5/10+(2*(C2*D2)*E2^0.4/1000)) -> 19.683967 | G2: =(800*B2*(E2^0.5))/10+(C2*D2*E2^0.7)/20 -> 1162026.7
B3: 300 | E3: =16.21*1.852 -> 30.02092 | F3: =0.004*(B3*E3^0.5/10+(2*(C3*D3)*E3^0.4/1000)) -> 0.6574962 | G3: =(800*B3*(E3^0.5))/10+(C3*D3*E3^0.7)/20 -> 131499.24
A5: tecnoSL | B5: 740 | C5: 58000 | D5: 100 | E5: 76 | F5: =0.004*(B5*E5^0.5/10+(2*(C5*D5)*E5^0.4/1000)) -> 264.90772 | G5: =(800*B5*(E5^0.5))/10+(C5*D5*E5^0.7)/20 -> 6527381.3

Sheet 貨物船
A1: 形式 | B1: 積載量 | C1: 係数 | D1: 定員（換算） | E1: 出力 | F1: ギア比 | G1: 最高速度 | H1: 維持費 | I1: 価格 | J1: 登場 | K1: 係数
A2: ばら | B2: ton
A3: c11c_bulk_barge | B3: 165 | C3: 2.2 | D3: =B3*C3 -> 363 | E3: 1050 | F3: 100 | G3: 25 | H3: =0.004*(D3*G3^0.5/10+(2*(E3*F3)*G3^0.4/1000))*K3*100 -> 358.15709 | I3: =(800*D3*(G3^0.5))/10+(E3*F3*G3^0.7)/20 -> 195170.92 | J3: 1942 | K3: 0.95
A4: P11C_Bulk_Boat | B4: 165 | C4: 2.2 | D4: =B4*C4 -> 363 | G4: 25 | H4: =0.004*(D4*G4^0.5/10+(2*(E4*F4)*G4^0.4/1000))*K4*100 -> 68.97 | I4: =(800*D4*(G4^0.5))/10+(E4*F4*G4^0.7)/20 -> 145200 | J4: 1942 | K4: 0.95
C5: 2.2 | D5: =B5*C5 -> 0 | H5: =0.004*(D5*G5^0.5/10+(2*(E5*F5)*G5^0.4/1000))*K5*100 -> 0 | I5: =(800*D5*(G5^0.5))/10+(E5*F5*G5^0.7)/20 -> 0
H6: =0.004*(D6*G6^0.5/10+(2*(E6*F6)*G6^0.4/1000))*K6*100 -> 0 | I6: =(800*D6*(G6^0.5))/10+(E6*F6*G6^0.7)/20 -> 0
H7: =0.004*(D7*G7^0.5/10+(2*(E7*F7)*G7^0.4/1000))*K7*100 -> 0 | I7: =(800*D7*(G7^0.5))/10+(E7*F7*G7^0.7)/20 -> 0
A8: 混載 | B8: 100 kg | H8: =0.004*(D8*G8^0.5/10+(2*(E8*F8)*G8^0.4/1000))*K8*100 -> 0 | I8: =(800*D8*(G8^0.5))/10+(E8*F8*G8^0.7)/20 -> 0
A9: C35_Goods_Barge | B9: 1500 | C9: 0.4 | D9: =B9*C9 -> 600 | E9: 880 | F9: 100 | G9: 34 | H9: =0.004*(D9*G9^0.5/10+(2*(E9*F9)*G9^0.4/1000))*K9*100 -> 428.45507 | I9: =(800*D9*(G9^0.5))/10+(E9*F9*G9^0.7)/20 -> 331824.01 | J9: 1938 | K9: 1
C10: 0.4 | D10: =B10*C10 -> 0 | H10: =0.004*(D10*G10^0.5/10+(2*(E10*F10)*G10^0.4/1000))*K10*100 -> 0 | I10: =(800*D10*(G10^0.5))/10+(E10*F10*G10^0.7)/20 -> 0
C11: 0.4 | D11: =B11*C11 -> 0 | H11: =0.004*(D11*G11^0.5/10+(2*(E11*F11)*G11^0.4/1000))*K11*100 -> 0 | I11: =(800*D11*(G11^0.5))/10+(E11*F11*G11^0.7)/20 -> 0
C12: 0.4 | D12: =B12*C12 -> 0 | H12: =0.004*(D12*G12^0.5/10+(2*(E12*F12)*G12^0.4/1000))*K12*100 -> 0 | I12: =(800*D12*(G12^0.5))/10+(E12*F12*G12^0.7)/20 -> 0
C13: 0.4 | D13: =B13*C13 -> 0 | H13: =0.004*(D13*G13^0.5/10+(2*(E13*F13)*G13^0.4/1000))*K13*100 -> 0 | I13: =(800*D13*(G13^0.5))/10+(E13*F13*G13^0.7)/20 -> 0
H14: =0.004*(D14*G14^0.5/10+(2*(E14*F14)*G14^0.4/1000))*K14*100 -> 0 | I14: =(800*D14*(G14^0.5))/10+(E14*F14*G14^0.7)/20 -> 0
H15: =0.004*(D15*G15^0.5/10+(2*(E15*F15)*G15^0.4/1000))*K15*100 -> 0 | I15: =(800*D15*(G15^0.5))/10+(E15*F15*G15^0.7)/20 -> 0
A16: パレット | B16: 1 ton | H16: =0.004*(D16*G16^0.5/10+(2*(E16*F16)*G16^0.4/1000))*K16*100 -> 0 | I16: =(800*D16*(G16^0.5))/10+(E16*F16*G16^0.7)/20 -> 0
A17: C273U_Cement_Barge | B17: 140 | C17: 3 | D17: =B17*C17 -> 420 | E17: 490 | F17: 110 | G17: 25 | H17: =0.004*(D17*G17^0.5/10+(2*(E17*F17)*G17^0.4/1000))*K17*100 -> 228.24937 | I17: =(800*D17*(G17^0.5))/10+(E17*F17*G17^0.7)/20 -> 193651.74 | J17: 1948 | K17: 0.95
C18: 3 | D18: =B18*C18 -> 0 | H18: =0.004*(D18*G18^0.5/10+(2*(E18*F18)*G18^0.4/1000))*K18*100 -> 0 | I18: =(800*D18*(G18^0.5))/10+(E18*F18*G18^0.7)/20 -> 0
C19: 3 | D19: =B19*C19 -> 0 | H19: =0.004*(D19*G19^0.5/10+(2*(E19*F19)*G19^0.4/1000))*K19*100 -> 0 | I19: =(800*D19*(G19^0.5))/10+(E19*F19*G19^0.7)/20 -> 0
C20: 3 | D20: =B20*C20 -> 0 | H20: =0.004*(D20*G20^0.5/10+(2*(E20*F20)*G20^0.4/1000))*K20*100 -> 0 | I20: =(800*D20*(G20^0.5))/10+(E20*F20*G20^0.7)/20 -> 0
C21: 3 | D21: =B21*C21 -> 0 | H21: =0.004*(D21*G21^0.5/10+(2*(E21*F21)*G21^0.4/1000))*K21*100 -> 0 | I21: =(800*D21*(G21^0.5))/10+(E21*F21*G21^0.7)/20 -> 0
C22: 3 | D22: =B22*C22 -> 0 | H22: =0.004*(D22*G22^0.5/10+(2*(E22*F22)*G22^0.4/1000))*K22*100 -> 0 | I22: =(800*D22*(G22^0.5))/10+(E22*F22*G22^0.7)/20 -> 0
H23: =0.004*(D23*G23^0.5/10+(2*(E23*F23)*G23^0.4/1000))*K23*100 -> 0 | I23: =(800*D23*(G23^0.5))/10+(E23*F23*G23^0.7)/20 -> 0
H24: =0.004*(D24*G24^0.5/10+(2*(E24*F24)*G24^0.4/1000))*K24*100 -> 0 | I24: =(800*D24*(G24^0.5))/10+(E24*F24*G24^0.7)/20 -> 0
H25: =0.004*(D25*G25^0.5/10+(2*(E25*F25)*G25^0.4/1000))*K25*100 -> 0 | I25: =(800*D25*(G25^0.5))/10+(E25*F25*G25^0.7)/20 -> 0
A26: 石油類 | B26: 1 ton | H26: =0.004*(D26*G26^0.5/10+(2*(E26*F26)*G26^0.4/1000))*K26*100 -> 0 | I26: =(800*D26*(G26^0.5))/10+(E26*F26*G26^0.7)/20 -> 0
C27: 2.5 | D27: =B27*C27 -> 0 | H27: =0.004*(D27*G27^0.5/10+(2*(E27*F27)*G27^0.4/1000))*K27*100 -> 0 | I27: =(800*D27*(G27^0.5))/10+(E27*F27*G27^0.7)/20 -> 0
C28: 2.5 | D28: =B28*C28 -> 0 | H28: =0.004*(D28*G28^0.5/10+(2*(E28*F28)*G28^0.4/1000))*K28*100 -> 0 | I28: =(800*D28*(G28^0.5))/10+(E28*F28*G28^0.7)/20 -> 0
C29: 2.5 | D29: =B29*C29 -> 0 | H29: =0.004*(D29*G29^0.5/10+(2*(E29*F29)*G29^0.4/1000))*K29*100 -> 0 | I29: =(800*D29*(G29^0.5))/10+(E29*F29*G29^0.7)/20 -> 0
H30: =0.004*(D30*G30^0.5/10+(2*(E30*F30)*G30^0.4/1000))*K30*100 -> 0 | I30: =(800*D30*(G30^0.5))/10+(E30*F30*G30^0.7)/20 -> 0
A31: 長物 | B31: 1 ton | H31: =0.004*(D31*G31^0.5/10+(2*(E31*F31)*G31^0.4/1000))*K31*100 -> 0 | I31: =(800*D31*(G31^0.5))/10+(E31*F31*G31^0.7)/20 -> 0
A32: c11c_wood_barge | B32: 140 | C32: 2 | D32: =B32*C32 -> 280 | E32: 1050 | F32: 100 | G32: 24 | H32: =0.004*(D32*G32^0.5/10+(2*(E32*F32)*G32^0.4/1000))*K32*100 -> 318.9112 | I32: =(800*D32*(G32^0.5))/10+(E32*F32*G32^0.7)/20 -> 158300.33 | J32: 1955 | K32: 0.9
A33: P11C_Wood_Boat | B33: 140 | C33: 2 | D33: =B33*C33 -> 280 | G33: 24 | H33: =0.004*(D33*G33^0.5/10+(2*(E33*F33)*G33^0.4/1000))*K33*100 -> 49.381713 | I33: =(800*D33*(G33^0.5))/10+(E33*F33*G33^0.7)/20 -> 109737.14 | J33: 1955 | K33: 0.9
C34: 2 | D34: =B34*C34 -> 0 | H34: =0.004*(D34*G34^0.5/10+(2*(E34*F34)*G34^0.4/1000))*K34*100 -> 0 | I34: =(800*D34*(G34^0.5))/10+(E34*F34*G34^0.7)/20 -> 0
H35: =0.004*(D35*G35^0.5/10+(2*(E35*F35)*G35^0.4/1000))*K35*100 -> 0 | I35: =(800*D35*(G35^0.5))/10+(E35*F35*G35^0.7)/20 -> 0
A36: 冷蔵加工食品 | B36: 100 kg | H36: =0.004*(D36*G36^0.5/10+(2*(E36*F36)*G36^0.4/1000))*K36*100 -> 0 | I36: =(800*D36*(G36^0.5))/10+(E36*F36*G36^0.7)/20 -> 0
C37: 0.5 | D37: =B37*C37 -> 0 | H37: =0.004*(D37*G37^0.5/10+(2*(E37*F37)*G37^0.4/1000))*K37*100 -> 0 | I37: =(800*D37*(G37^0.5))/10+(E37*F37*G37^0.7)/20 -> 0
C38: 0.5 | D38: =B38*C38 -> 0 | H38: =0.004*(D38*G38^0.5/10+(2*(E38*F38)*G38^0.4/1000))*K38*100 -> 0 | I38: =(800*D38*(G38^0.5))/10+(E38*F38*G38^0.7)/20 -> 0
H39: =0.004*(D39*G39^0.5/10+(2*(E39*F39)*G39^0.4/1000))*K39*100 -> 0 | I39: =(800*D39*(G39^0.5))/10+(E39*F39*G39^0.7)/20 -> 0
H40: =0.004*(D40*G40^0.5/10+(2*(E40*F40)*G40^0.4/1000))*K40*100 -> 0 | I40: =(800*D40*(G40^0.5))/10+(E40*F40*G40^0.7)/20 -> 0
...

Sheet 貨物係数
A1: カテゴリ番号 | B1: カテゴリ | C1: 係数
A2: 0 | B2: 旅客 | C2: 1
A3: 0 | B3: コンクリート | C3: 10
A4: 0 | B4: 家畜 | C4: 14
A6: 11 | B6: 混載 | C6: 12
A7: 12 | B7: 冷蔵 | C7: =C$6+2 -> 14
A8: 13 | B8: 冷凍 | C8: =C$6+4 -> 16
A9: 14 | B9: 小荷物 | C9: 1.53
A11: 21 | B11: ばら | C11: 14
A12: 22 | B12: 粉粒体 | C12: 10.77
A13: 23 | B13: 廃棄物 | C13: 3.93
A14: 24 | B14: 長物 | C14: 14
A15: 25 | B15: 水産物 | C15: 14
A17: 31 | B17: 液体 | C17: 14
A18: 32 | B18: 気体 | C18: 14
